Workbook

Sheet Predloge
A1: 2025
B2: 51☻ | E2: POČ
B3: 52☻ | E3: ŠOŠ
B4: 51 | E4: PIN
B5: 52 | E5: KON
B6: KVIT | E6: ORO
B7: KVIT☻ | E7: MIO
B8: U | E8: BOŽ
B9: U☻ | E9: TOM
B10: 12-20 | E10: MŠŠ
B11: X | E11: ŽIV
B12: D | E12: TAL
B13: BOL | E13: PIR
... B21: ☺ | E21: DIV
B22: U☺
B23: 51☺
B24: 52☺
B25: 51¶
B26: 52¶
B27: KVIT☺
B28: KO
B29: Rt
B30: Rt☻
B31: Rt☺
B32: Am
B33: Am☻
... B53: .

Sheet januar
A1: praznik | B1: =Predloge!$A$1 -> 2025 | D1: =Predloge!$E$2 -> POČ | E1: =Predloge!$E$3 -> ŠOŠ | F1: =Predloge!$E$4 -> PIN | G1: =Predloge!$E$5 -> KON | H1: =Predloge!$E$6 -> ORO | I1: =Predloge!$E$7 -> MIO | J1: =Predloge!$E$8 -> BOŽ | K1: =Predloge!$E$9 -> TOM | L1: =Predloge!$E$10 -> MŠŠ | M1: =Predloge!$E$11 -> ŽIV | N1: =Predloge!$E$12 -> TAL | O1: =Predloge!$E$13 -> PIR | P1: =Predloge!$E$14 -> GNE | Q1: =Predloge!$E$15 -> BUT | R1: =Predloge!$E$16 -> ŽRJ | S1: =Predloge!$E$17 -> NOV3 | T1: =Predloge!$E$18 -> JNK | U1: =Predloge!$E$19 -> ŠTU | V1: ZUN | W1: TX | X1: ☻ | Y1: ☺ | Z1: =Predloge!$B$4 -> 51 | AA1: =Predloge!$B$5 -> 52 | AB1: =Predloge!$B$25 -> 51¶ | AC1: =Predloge!$B$26 -> 52¶ | AD1: =Predloge!$B$8 -> U | AE1: =Predloge!$B$6 -> KVIT | AF1: Brez | AG1: X | AH1: Op | AJ1: =Predloge!$E$2 -> POČ | AK1: =Predloge!$E$3 -> ŠOŠ | AL1: =Predloge!$E$4 -> PIN | AM1: =Predloge!$E$5 -> KON | AN1: =Predloge!$E$6 -> ORO | AO1: =Predloge!$E$7 -> MIO | AP1: =Predloge!$E$8 -> BOŽ | AQ1: =Predloge!$E$9 -> TOM | AR1: =Predloge!$E$10 -> MŠŠ | AS1: =Predloge!$E$11 -> ŽIV | AT1: =Predloge!$E$12 -> TAL | AU1: =Predloge!$E$13 -> PIR | AV1: =Predloge!$E$14 -> GNE | AW1: =Predloge!$E$15 -> BUT | AX1: =Predloge!$E$16 -> ŽRJ | AY1: =Predloge!$E$17 -> NOV3 | AZ1: =Predloge!$E$18 -> JNK | BA1: =Predloge!$E$19 -> ŠTU
A2: 1 | B2: 45658 | C2: =TEXT(B2,"Ddd") -> Wed | D2: =Predloge!$B$14 -> ☻ | R2: =Predloge!$B$21 -> ☺ | V2: ŽRJ | W2: ŽIV | X2: =COUNTIF(AJ2:BA2,"☻") -> 1 | Y2: =COUNTIF(AJ2:BA2,"☺") -> 1 | Z2: =COUNTIF(D2:V2,"51")+COUNTIF(D2:V2,"51$")+COUNTIF(D2:V2,"51☻") -> 0 | AA2: =COUNTIF(D2:V2,"52")+COUNTIF(D2:V2,"52$")+COUNTIF(D2:V2,"52☻") -> 0 | AB2: =COUNTIF(D2:V2,"51¶") -> 0 | AC2: =COUNTIF(D2:V2,"52¶") -> 0 | AD2: =COUNTIF(D2:V2,"U")+COUNTIF(D2:V2,"U☻")+COUNTIF(D2:V2,"U☺") -> 0 | AE2: =COUNTIF(D2:V2,"KVIT")+COUNTIF(D2:V2,"KVIT☻")+COUNTIF(D2:V2,"kvit$") -> 0 | AF2: =COUNTBLANK(D2:U2)-3 -> 13 | AG2: =COUNTIF(D2:V2,"x") -> 0 | AH2: =COUNTIF(D2:V2,"51")+COUNTIF(D2:V2,"51☻")+COUNTIF(D2:V2,"2")+COUNTIF(D2:V2,"52")+COUNTIF(D2:V2,"52☻")+COUNTIF(D2:V2,"51$")+COUNTIF(D2:V2,"52$") -> 0 | AI2: =Predloge!$B$2 -> 51☻ | AJ2: =RIGHT(D2,1) -> ☻ | AK2: =RIGHT(E2,1) | AL2: =RIGHT(F2,1) | AM2: =RIGHT(G2,1) | AN2: =RIGHT(H2,1) | AO2: =RIGHT(I2,1) | AP2: =RIGHT(J2,1) | AQ2: =RIGHT(K2,1) | ... BA2: =RIGHT(U2,1)
A3: 1 | B3: 45659 | C3: =TEXT(B3,"Ddd") -> Thu | G3: =Predloge!$B$14 -> ☻ | M3: =Predloge!$B$21 -> ☺ | V3: ŽIV | W3: POČ | X3: =COUNTIF(AJ3:BA3,"☻") -> 1 | Y3: =COUNTIF(AJ3:BA3,"☺") -> 1 | Z3: =COUNTIF(D3:V3,"51")+COUNTIF(D3:V3,"51$")+COUNTIF(D3:V3,"51☻") -> 0 | AA3: =COUNTIF(D3:V3,"52")+COUNTIF(D3:V3,"52$")+COUNTIF(D3:V3,"52☻") -> 0 | AB3: =COUNTIF(D3:V3,"51¶") -> 0 | AC3: =COUNTIF(D3:V3,"52¶") -> 0 | AD3: =COUNTIF(D3:V3,"U")+COUNTIF(D3:V3,"U☻")+COUNTIF(D3:V3,"U☺") -> 0 | AE3: =COUNTIF(D3:V3,"KVIT")+COUNTIF(D3:V3,"KVIT☻")+COUNTIF(D3:V3,"kvit$") -> 0 | AF3: =COUNTBLANK(D3:U3)-3 -> 13 | AG3: =COUNTIF(D3:V3,"x") -> 0 | AH3: =COUNTIF(D3:V3,"51")+COUNTIF(D3:V3,"51☻")+COUNTIF(D3:V3,"2")+COUNTIF(D3:V3,"52")+COUNTIF(D3:V3,"52☻")+COUNTIF(D3:V3,"51$")+COUNTIF(D3:V3,"52$") -> 0 | AI3: =Predloge!$B$3 -> 52☻ | AJ3: =RIGHT(D3,1) | AK3: =RIGHT(E3,1) | AL3: =RIGHT(F3,1) | AM3: =RIGHT(G3,1) -> ☻ | AN3: =RIGHT(H3,1) | AO3: =RIGHT(I3,1) | AP3: =RIGHT(J3,1) | AQ3: =RIGHT(K3,1) | ... BA3: =RIGHT(U3,1)
B4: 45660 | C4: =TEXT(B4,"Ddd") -> Fri | D4: =Predloge!$B$6 -> KVIT | E4: =Predloge!$B$12 -> D | F4: =Predloge!$B$12 -> D | G4: =Predloge!$B$11 -> X | H4: =Predloge!$B$12 -> D | I4: =Predloge!$B$12 -> D | J4: =Predloge!$B$12 -> D | K4: =Predloge!$B$5 -> 52 | L4: =Predloge!$B$6 -> KVIT | M4: =Predloge!$B$11 -> X | N4: =Predloge!$B$13 -> BOL | O4: =Predloge!$B$12 -> D | P4: =Predloge!$B$4 -> 51 | Q4: =Predloge!$B$12 -> D | R4: =Predloge!$B$4 -> 51 | T4: =Predloge!$B$12 -> D | U4: =Predloge!$B$12 -> D | V4: MI/DIV | W4: TOM | X4: =COUNTIF(AJ4:BA4,"☻") -> 0 | Y4: =COUNTIF(AJ4:BA4,"☺") -> 0 | Z4: =COUNTIF(D4:V4,"51")+COUNTIF(D4:V4,"51$")+COUNTIF(D4:V4,"51☻") -> 2 | AA4: =COUNTIF(D4:V4,"52")+COUNTIF(D4:V4,"52$")+COUNTIF(D4:V4,"52☻") -> 1 | AB4: =COUNTIF(D4:V4,"51¶") -> 0 | AC4: =COUNTIF(D4:V4,"52¶") -> 0 | AD4: =COUNTIF(D4:V4,"U")+COUNTIF(D4:V4,"U☻")+COUNTIF(D4:V4,"U☺") -> 0 | AE4: =COUNTIF(D4:V4,"KVIT")+COUNTIF(D4:V4,"KVIT☻")+COUNTIF(D4:V4,"kvit$") -> 2 | AF4: =COUNTBLANK(D4:U4)-3 -> -2 | AG4: =COUNTIF(D4:V4,"x") -> 2 | AH4: =COUNTIF(D4:V4,"51")+COUNTIF(D4:V4,"51☻")+COUNTIF(D4:V4,"2")+COUNTIF(D4:V4,"52")+COUNTIF(D4:V4,"52☻")+COUNTIF(D4:V4,"51$")+COUNTIF(D4:V4,"52$") -> 3 | AI4: =Predloge!$B$4 -> 51 | AJ4: =RIGHT(D4,1) -> T | AK4: =RIGHT(E4,1) -> D | AL4: =RIGHT(F4,1) -> D | AM4: =RIGHT(G4,1) -> X | AN4: =RIGHT(H4,1) -> D | AO4: =RIGHT(I4,1) -> D | AP4: =RIGHT(J4,1) -> D | AQ4: =RIGHT(K4,1) -> 2 | ... BA4: =RIGHT(U4,1) -> D
B5: 45661 | C5: =TEXT(B5,"Ddd") -> Sat | D5: =Predloge!$B$14 -> ☻ | R5: =Predloge!$B$21 -> ☺ | V5: ŽRJ | W5: TOM | X5: =COUNTIF(AJ5:BA5,"☻") -> 1 | Y5: =COUNTIF(AJ5:BA5,"☺") -> 1 | Z5: =COUNTIF(D5:V5,"51")+COUNTIF(D5:V5,"51$")+COUNTIF(D5:V5,"51☻") -> 0 | AA5: =COUNTIF(D5:V5,"52")+COUNTIF(D5:V5,"52$")+COUNTIF(D5:V5,"52☻") -> 0 | AB5: =COUNTIF(D5:V5,"51¶") -> 0 | AC5: =COUNTIF(D5:V5,"52¶") -> 0 | AD5: =COUNTIF(D5:V5,"U")+COUNTIF(D5:V5,"U☻")+COUNTIF(D5:V5,"U☺") -> 0 | AE5: =COUNTIF(D5:V5,"KVIT")+COUNTIF(D5:V5,"KVIT☻")+COUNTIF(D5:V5,"kvit$") -> 0 | AF5: =COUNTBLANK(D5:U5)-3 -> 13 | AG5: =COUNTIF(D5:V5,"x") -> 0 | AH5: =COUNTIF(D5:V5,"51")+COUNTIF(D5:V5,"51☻")+COUNTIF(D5:V5,"2")+COUNTIF(D5:V5,"52")+COUNTIF(D5:V5,"52☻")+COUNTIF(D5:V5,"51$")+COUNTIF(D5:V5,"52$") -> 0 | AI5: =Predloge!$B$5 -> 52 | AJ5: =RIGHT(D5,1) -> ☻ | AK5: =RIGHT(E5,1) | AL5: =RIGHT(F5,1) | AM5: =RIGHT(G5,1) | AN5: =RIGHT(H5,1) | AO5: =RIGHT(I5,1) | AP5: =RIGHT(J5,1) | AQ5: =RIGHT(K5,1) | ... BA5: =RIGHT(U5,1)
B6: 45662 | C6: =TEXT(B6,"Ddd") -> Sun | L6: =Predloge!$B$14 -> ☻ | V6: DIV | W6: TOM | X6: =COUNTIF(AJ6:BA6,"☻") -> 1 | Y6: =COUNTIF(AJ6:BA6,"☺") -> 0 | Z6: =COUNTIF(D6:V6,"51")+COUNTIF(D6:V6,"51$")+COUNTIF(D6:V6,"51☻") -> 0 | AA6: =COUNTIF(D6:V6,"52")+COUNTIF(D6:V6,"52$")+COUNTIF(D6:V6,"52☻") -> 0 | AB6: =COUNTIF(D6:V6,"51¶") -> 0 | AC6: =COUNTIF(D6:V6,"52¶") -> 0 | AD6: =COUNTIF(D6:V6,"U")+COUNTIF(D6:V6,"U☻")+COUNTIF(D6:V6,"U☺") -> 0 | AE6: =COUNTIF(D6:V6,"KVIT")+COUNTIF(D6:V6,"KVIT☻")+COUNTIF(D6:V6,"kvit$") -> 0 | AF6: =COUNTBLANK(D6:U6)-3 -> 14 | AG6: =COUNTIF(D6:V6,"x") -> 0 | AH6: =COUNTIF(D6:V6,"51")+COUNTIF(D6:V6,"51☻")+COUNTIF(D6:V6,"2")+COUNTIF(D6:V6,"52")+COUNTIF(D6:V6,"52☻")+COUNTIF(D6:V6,"51$")+COUNTIF(D6:V6,"52$") -> 0 | AI6: =Predloge!$B$6 -> KVIT | AJ6: =RIGHT(D6,1) | AK6: =RIGHT(E6,1) | AL6: =RIGHT(F6,1) | AM6: =RIGHT(G6,1) | AN6: =RIGHT(H6,1) | AO6: =RIGHT(I6,1) | AP6: =RIGHT(J6,1) | AQ6: =RIGHT(K6,1) | ... BA6: =RIGHT(U6,1)
B7: 45663 | C7: =TEXT(B7,"Ddd") -> Mon | D7: =Predloge!$B$4 -> 51 | E7: MF | F7: =Predloge!$B$26 -> 52¶ | G7: =Predloge!$B$7 -> KVIT☻ | H7: =Predloge!$B$12 -> D | I7: =Predloge!$B$12 -> D | J7: =Predloge!$B$5 -> 52 | K7: =[1]Predloge!$B$6 -> KVIT | L7: =Predloge!$B$11 -> X | M7: =Predloge!$B$12 -> D | N7: =Predloge!$B$12 -> D | O7: =Predloge!$B$12 -> D | P7: =Predloge!$B$5 -> 52 | Q7: =Predloge!$B$6 -> KVIT | R7: =Predloge!$B$23 -> 51☺ | T7: MF | U7: NPK | V7: ŽRJ | W7: =Predloge!$E$2 -> POČ | X7: =COUNTIF(AJ7:BA7,"☻") -> 1 | Y7: =COUNTIF(AJ7:BA7,"☺") -> 1 | Z7: =COUNTIF(D7:V7,"51")+COUNTIF(D7:V7,"51$")+COUNTIF(D7:V7,"51☻") -> 1 | AA7: =COUNTIF(D7:V7,"52")+COUNTIF(D7:V7,"52$")+COUNTIF(D7:V7,"52☻") -> 2 | AB7: =COUNTIF(D7:V7,"51¶") -> 0 | AC7: =COUNTIF(D7:V7,"52¶") -> 1 | AD7: =COUNTIF(D7:V7,"U")+COUNTIF(D7:V7,"U☻")+COUNTIF(D7:V7,"U☺") -> 0 | AE7: =COUNTIF(D7:V7,"KVIT")+COUNTIF(D7:V7,"KVIT☻")+COUNTIF(D7:V7,"kvit$") -> 3 | AF7: =COUNTBLANK(D7:U7)-3 -> -2 | AG7: =COUNTIF(D7:V7,"x") -> 1 | AH7: =COUNTIF(D7:V7,"51")+COUNTIF(D7:V7,"51☻")+COUNTIF(D7:V7,"2")+COUNTIF(D7:V7,"52")+COUNTIF(D7:V7,"52☻")+COUNTIF(D7:V7,"51$")+COUNTIF(D7:V7,"52$") -> 3 | AI7: =Predloge!$B$7 -> KVIT☻ | AJ7: =RIGHT(D7,1) -> 1 | AK7: =RIGHT(E7,1) -> F | AL7: =RIGHT(F7,1) -> ¶ | AM7: =RIGHT(G7,1) -> ☻ | AN7: =RIGHT(H7,1) -> D | AO7: =RIGHT(I7,1) -> D | AP7: =RIGHT(J7,1) -> 2 | AQ7: =RIGHT(K7,1) -> T | ... BA7: =RIGHT(U7,1) -> K
B8: 45664 | C8: =TEXT(B8,"Ddd") -> Tue | D8: =Predloge!$B$26 -> 52¶ | E8: =Predloge!$B$12 -> D | F8: =[1]Predloge!$B$6 -> KVIT | G8: =Predloge!$B$11 -> X | H8: =Predloge!$B$12 -> D | I8: =Predloge!$B$32 -> Am | J8: =Predloge!$B$5 -> 52 | K8: =Predloge!$B$12 -> D | L8: =Predloge!$B$6 -> KVIT | M8: =Predloge!$B$12 -> D | N8: =Predloge!$B$12 -> D | O8: =Predloge!$B$12 -> D | P8: =Predloge!$B$4 -> 51 | Q8: =Predloge!$B$7 -> KVIT☻ | R8: =Predloge!$B$11 -> X | T8: =Predloge!$B$23 -> 51☺ | U8: NPK | V8: JNK | W8: =Predloge!$E$2 -> POČ | X8: =COUNTIF(AJ8:BA8,"☻") -> 1 | Y8: =COUNTIF(AJ8:BA8,"☺") -> 1 | Z8: =COUNTIF(D8:V8,"51")+COUNTIF(D8:V8,"51$")+COUNTIF(D8:V8,"51☻") -> 1 | AA8: =COUNTIF(D8:V8,"52")+COUNTIF(D8:V8,"52$")+COUNTIF(D8:V8,"52☻") -> 1 | AB8: =COUNTIF(D8:V8,"51¶") -> 0 | AC8: =COUNTIF(D8:V8,"52¶") -> 1 | AD8: =COUNTIF(D8:V8,"U")+COUNTIF(D8:V8,"U☻")+COUNTIF(D8:V8,"U☺") -> 0 | AE8: =COUNTIF(D8:V8,"KVIT")+COUNTIF(D8:V8,"KVIT☻")+COUNTIF(D8:V8,"kvit$") -> 3 | AF8: =COUNTBLANK(D8:U8)-3 -> -2 | AG8: =COUNTIF(D8:V8,"x") -> 2 | AH8: =COUNTIF(D8:V8,"51")+COUNTIF(D8:V8,"51☻")+COUNTIF(D8:V8,"2")+COUNTIF(D8:V8,"52")+COUNTIF(D8:V8,"52☻")+COUNTIF(D8:V8,"51$")+COUNTIF(D8:V8,"52$") -> 2 | AI8: =Predloge!$B$8 -> U | AJ8: =RIGHT(D8,1) -> ¶ | AK8: =RIGHT(E8,1) -> D | AL8: =RIGHT(F8,1) -> T | AM8: =RIGHT(G8,1) -> X | AN8: =RIGHT(H8,1) -> D | AO8: =RIGHT(I8,1) -> m | AP8: =RIGHT(J8,1) -> 2 | AQ8: =RIGHT(K8,1) -> D | ... BA8: =RIGHT(U8,1) -> K
B9: 45665 | C9: =TEXT(B9,"Ddd") -> Wed | D9: =Predloge!$B$5 -> 52 | E9: =Predloge!$B$7 -> KVIT☻ | F9: =Predloge!$B$6 -> KVIT | G9: =Predloge!$B$4 -> 51 | H9: =Predloge!$B$12 -> D | I9: =Predloge!$B$26 -> 52¶ | J9: =Predloge!$B$23 -> 51☺ | K9: =Predloge!$B$6 -> KVIT | L9: =Predloge!$B$6 -> KVIT | M9: =Predloge!$B$12 -> D | N9: =Predloge!$B$12 -> D | O9: =Predloge!$B$12 -> D | P9: =Predloge!$B$35 -> Ta | Q9: =Predloge!$B$11 -> X | R9: =Predloge!$B$35 -> Ta | T9: =Predloge!$B$11 -> X | U9: NPK | V9: BOŽ | W9: =Predloge!$E$2 -> POČ | X9: =COUNTIF(AJ9:BA9,"☻") -> 1 | Y9: =COUNTIF(AJ9:BA9,"☺") -> 1 | Z9: =COUNTIF(D9:V9,"51")+COUNTIF(D9:V9,"51$")+COUNTIF(D9:V9,"51☻") -> 1 | AA9: =COUNTIF(D9:V9,"52")+COUNTIF(D9:V9,"52$")+COUNTIF(D9:V9,"52☻") -> 1 | AB9: =COUNTIF(D9:V9,"51¶") -> 0 | AC9: =COUNTIF(D9:V9,"52¶") -> 1 | AD9: =COUNTIF(D9:V9,"U")+COUNTIF(D9:V9,"U☻")+COUNTIF(D9:V9,"U☺") -> 0 | AE9: =COUNTIF(D9:V9,"KVIT")+COUNTIF(D9:V9,"KVIT☻")+COUNTIF(D9:V9,"kvit$") -> 4 | AF9: =COUNTBLANK(D9:U9)-3 -> -2 | AG9: =COUNTIF(D9:V9,"x") -> 2 | AH9: =COUNTIF(D9:V9,"51")+COUNTIF(D9:V9,"51☻")+COUNTIF(D9:V9,"2")+COUNTIF(D9:V9,"52")+COUNTIF(D9:V9,"52☻")+COUNTIF(D9:V9,"51$")+COUNTIF(D9:V9,"52$") -> 2 | AI9: =Predloge!$B$9 -> U☻ | AJ9: =RIGHT(D9,1) -> 2 | AK9: =RIGHT(E9,1) -> ☻ | AL9: =RIGHT(F9,1) -> T | AM9: =RIGHT(G9,1) -> 1 | AN9: =RIGHT(H9,1) -> D | AO9: =RIGHT(I9,1) -> ¶ | AP9: =RIGHT(J9,1) -> ☺ | AQ9: =RIGHT(K9,1) -> T | ... BA9: =RIGHT(U9,1) -> K
B10: 45666 | C10: =TEXT(B10,"Ddd") -> Thu | D10: =Predloge!$B$6 -> KVIT | E10: =Predloge!$B$11 -> X | F10: =Predloge!$B$6 -> KVIT | G10: =Predloge!$B$26 -> 52¶ | H10: =Predloge!$B$12 -> D | I10: =Predloge!$B$4 -> 51 | J10: =Predloge!$B$11 -> X | K10: =Predloge!$B$6 -> KVIT | L10: =Predloge!$B$7 -> KVIT☻ | M10: =Predloge!$B$12 -> D | N10: =Predloge!$B$12 -> D | O10: =Predloge!$B$23 -> 51☺ | P10: =Predloge!$B$5 -> 52 | Q10: =[1]Predloge!$B$6 -> KVIT | R10: NPK | T10: =Predloge!$B$5 -> 52 | U10: NPK | V10: PIR | W10: =Predloge!$E$2 -> POČ | X10: =COUNTIF(AJ10:BA10,"☻") -> 1 | Y10: =COUNTIF(AJ10:BA10,"☺") -> 1 | Z10: =COUNTIF(D10:V10,"51")+COUNTIF(D10:V10,"51$")+COUNTIF(D10:V10,"51☻") -> 1 | AA10: =COUNTIF(D10:V10,"52")+COUNTIF(D10:V10,"52$")+COUNTIF(D10:V10,"52☻") -> 2 | AB10: =COUNTIF(D10:V10,"51¶") -> 0 | AC10: =COUNTIF(D10:V10,"52¶") -> 1 | AD10: =COUNTIF(D10:V10,"U")+COUNTIF(D10:V10,"U☻")+COUNTIF(D10:V10,"U☺") -> 0 | AE10: =COUNTIF(D10:V10,"KVIT")+COUNTIF(D10:V10,"KVIT☻")+COUNTIF(D10:V10,"kvit$") -> 5 | AF10: =COUNTBLANK(D10:U10)-3 -> -2 | AG10: =COUNTIF(D10:V10,"x") -> 2 | AH10: =COUNTIF(D10:V10,"51")+COUNTIF(D10:V10,"51☻")+COUNTIF(D10:V10,"2")+COUNTIF(D10:V10,"52")+COUNTIF(D10:V10,"52☻")+COUNTIF(D10:V10,"51$")+COUNTIF(D10:V10,"52$") -> 3 | AI10: =Predloge!$B$10 -> 12-20 | AJ10: =RIGHT(D10,1) -> T | AK10: =RIGHT(E10,1) -> X | AL10: =RIGHT(F10,1) -> T | AM10: =RIGHT(G10,1) -> ¶ | AN10: =RIGHT(H10,1) -> D | AO10: =RIGHT(I10,1) -> 1 | AP10: =RIGHT(J10,1) -> X | AQ10: =RIGHT(K10,1) -> T | ... BA10: =RIGHT(U10,1) -> K
B11: 45667 | C11: =TEXT(B11,"Ddd") -> Fri | D11: =Predloge!$B$6 -> KVIT | E11: =Predloge!$B$6 -> KVIT | F11: =Predloge!$B$6 -> KVIT | G11: =Predloge!$B$6 -> KVIT | H11: =Predloge!$B$12 -> D | I11: =Predloge!$B$4 -> 51 | J11: =Predloge!$B$4 -> 51 | K11: =Predloge!$B$7 -> KVIT☻ | L11: =Predloge!$B$11 -> X | M11: =Predloge!$B$12 -> D | N11: =Predloge!$B$12 -> D | O11: =Predloge!$B$11 -> X | P11: =Predloge!$B$5 -> 52 | Q11: =Predloge!$B$6 -> KVIT | R11: =Predloge!$B$5 -> 52 | T11: =Predloge!$B$6 -> KVIT | U11: =Predloge!$B$23 -> 51☺ | V11: ŠTU | W11: =Predloge!$E$2 -> POČ | X11: =COUNTIF(AJ11:BA11,"☻") -> 1 | Y11: =COUNTIF(AJ11:BA11,"☺") -> 1 | Z11: =COUNTIF(D11:V11,"51")+COUNTIF(D11:V11,"51$")+COUNTIF(D11:V11,"51☻") -> 2 | AA11: =COUNTIF(D11:V11,"52")+COUNTIF(D11:V11,"52$")+COUNTIF(D11:V11,"52☻") -> 2 | AB11: =COUNTIF(D11:V11,"51¶") -> 0 | AC11: =COUNTIF(D11:V11,"52¶") -> 0 | AD11: =COUNTIF(D11:V11,"U")+COUNTIF(D11:V11,"U☻")+COUNTIF(D11:V11,"U☺") -> 0 | AE11: =COUNTIF(D11:V11,"KVIT")+COUNTIF(D11:V11,"KVIT☻")+COUNTIF(D11:V11,"kvit$") -> 7 | AF11: =COUNTBLANK(D11:U11)-3 -> -2 | AG11: =COUNTIF(D11:V11,"x") -> 2 | AH11: =COUNTIF(D11:V11,"51")+COUNTIF(D11:V11,"51☻")+COUNTIF(D11:V11,"2")+COUNTIF(D11:V11,"52")+COUNTIF(D11:V11,"52☻")+COUNTIF(D11:V11,"51$")+COUNTIF(D11:V11,"52$") -> 4 | AI11: =Predloge!$B$11 -> X | AJ11: =RIGHT(D11,1) -> T | AK11: =RIGHT(E11,1) -> T | AL11: =RIGHT(F11,1) -> T | AM11: =RIGHT(G11,1) -> T | AN11: =RIGHT(H11,1) -> D | AO11: =RIGHT(I11,1) -> 1 | AP11: =RIGHT(J11,1) -> 1 | AQ11: =RIGHT(K11,1) -> ☻ | ... BA11: =RIGHT(U11,1) -> ☺
B12: 45668 | C12: =TEXT(B12,"Ddd") -> Sat | E12: =Predloge!$B$14 -> ☻ | T12: =Predloge!$B$21 -> ☺ | V12: JNK | W12: ŽRJ | X12: =COUNTIF(AJ12:BA12,"☻") -> 1 | Y12: =COUNTIF(AJ12:BA12,"☺") -> 1 | Z12: =COUNTIF(D12:V12,"51")+COUNTIF(D12:V12,"51$")+COUNTIF(D12:V12,"51☻") -> 0 | AA12: =COUNTIF(D12:V12,"52")+COUNTIF(D12:V12,"52$")+COUNTIF(D12:V12,"52☻") -> 0 | AB12: =COUNTIF(D12:V12,"51¶") -> 0 | AC12: =COUNTIF(D12:V12,"52¶") -> 0 | AD12: =COUNTIF(D12:V12,"U")+COUNTIF(D12:V12,"U☻")+COUNTIF(D12:V12,"U☺") -> 0 | AE12: =COUNTIF(D12:V12,"KVIT")+COUNTIF(D12:V12,"KVIT☻")+COUNTIF(D12:V12,"kvit$") -> 0 | AF12: =COUNTBLANK(D12:U12)-3 -> 13 | AG12: =COUNTIF(D12:V12,"x") -> 0 | AH12: =COUNTIF(D12:V12,"51")+COUNTIF(D12:V12,"51☻")+COUNTIF(D12:V12,"2")+COUNTIF(D12:V12,"52")+COUNTIF(D12:V12,"52☻")+COUNTIF(D12:V12,"51$")+COUNTIF(D12:V12,"52$") -> 0 | AI12: =Predloge!$B$12 -> D | AJ12: =RIGHT(D12,1) | AK12: =RIGHT(E12,1) -> ☻ | AL12: =RIGHT(F12,1) | AM12: =RIGHT(G12,1) | AN12: =RIGHT(H12,1) | AO12: =RIGHT(I12,1) | AP12: =RIGHT(J12,1) | AQ12: =RIGHT(K12,1) | ... BA12: =RIGHT(U12,1)
B13: 45669 | C13: =TEXT(B13,"Ddd") -> Sun | K13: =Predloge!$B$14 -> ☻ | U13: =Predloge!$B$21 -> ☺ | V13: ŠTU | W13: ŽRJ | X13: =COUNTIF(AJ13:BA13,"☻") -> 0 | Y13: =COUNTIF(AJ13:BA13,"☺") -> 1 | Z13: =COUNTIF(D13:V13,"51")+COUNTIF(D13:V13,"51$")+COUNTIF(D13:V13,"51☻") -> 0 | AA13: =COUNTIF(D13:V13,"52")+COUNTIF(D13:V13,"52$")+COUNTIF(D13:V13,"52☻") -> 0 | AB13: =COUNTIF(D13:V13,"51¶") -> 0 | AC13: =COUNTIF(D13:V13,"52¶") -> 0 | AD13: =COUNTIF(D13:V13,"U")+COUNTIF(D13:V13,"U☻")+COUNTIF(D13:V13,"U☺") -> 0 | AE13: =COUNTIF(D13:V13,"KVIT")+COUNTIF(D13:V13,"KVIT☻")+COUNTIF(D13:V13,"kvit$") -> 0 | AF13: =COUNTBLANK(D13:U13)-3 -> 13 | AG13: =COUNTIF(D13:V13,"x") -> 0 | AH13: =COUNTIF(D13:V13,"51")+COUNTIF(D13:V13,"51☻")+COUNTIF(D13:V13,"2")+COUNTIF(D13:V13,"52")+COUNTIF(D13:V13,"52☻")+COUNTIF(D13:V13,"51$")+COUNTIF(D13:V13,"52$") -> 0 | AI13: =Predloge!$B$13 -> BOL | AJ13: =RIGHT(D13,1) | AK13: =RIGHT(E13,1) | AL13: =RIGHT(F13,1) | AM13: =RIGHT(G13,1) | AN13: =RIGHT(H13,1) | AO13: =RIGHT(I13,1) | AP13: =RIGHT(J13,1) | AQ13: =RIGHT(K14,1) -> X | AR13: =RIGHT(L13,1) | AS13: =RIGHT(M13,1) | AT13: =RIGHT(N13,1) | AU13: =RIGHT(O13,1) | AV13: =RIGHT(P13,1) | AW13: =RIGHT(Q13,1) | AX13: =RIGHT(R13,1) | AY13: =RIGHT(S13,1) | ... BA13: =RIGHT(U13,1) -> ☺
B14: 45670 | C14: =TEXT(B14,"Ddd") -> Mon | D14: =Predloge!$B$6 -> KVIT | E14: MF | F14: =Predloge!$B$6 -> KVIT | G14: =Predloge!$B$6 -> KVIT | H14: KO | I14: =Predloge!$B$5 -> 52 | J14: =Predloge!$B$4 -> 51 | K14: =Predloge!$B$11 -> X | L14: =Predloge!$B$6 -> KVIT | M14: =Predloge!$B$12 -> D | N14: =Predloge!$B$6 -> KVIT | O14: =Predloge!$B$23 -> 51☺ | P14: =Predloge!$B$4 -> 51 | Q14: =Predloge!$B$16 -> ☻ | R14: =Predloge!$B$26 -> 52¶ | T14: MF | U14: =Predloge!$B$11 -> X | V14: PIR | W14: =Predloge!$E$5 -> KON | X14: =COUNTIF(AJ14:BA14,"☻") -> 1 | Y14: =COUNTIF(AJ14:BA14,"☺") -> 1 | Z14: =COUNTIF(D14:V14,"51")+COUNTIF(D14:V14,"51$")+COUNTIF(D14:V14,"51☻") -> 2 | AA14: =COUNTIF(D14:V14,"52")+COUNTIF(D14:V14,"52$")+COUNTIF(D14:V14,"52☻") -> 1 | AB14: =COUNTIF(D14:V14,"51¶") -> 0 | AC14: =COUNTIF(D14:V14,"52¶") -> 1 | AD14: =COUNTIF(D14:V14,"U")+COUNTIF(D14:V14,"U☻")+COUNTIF(D14:V14,"U☺") -> 0 | AE14: =COUNTIF(D14:V14,"KVIT")+COUNTIF(D14:V14,"KVIT☻")+COUNTIF(D14:V14,"kvit$") -> 5 | AF14: =COUNTBLANK(D14:U14)-3 -> -2 | AG14: =COUNTIF(D14:V14,"x") -> 2 | AH14: =COUNTIF(D14:V14,"51")+COUNTIF(D14:V14,"51☻")+COUNTIF(D14:V14,"2")+COUNTIF(D14:V14,"52")+COUNTIF(D14:V14,"52☻")+COUNTIF(D14:V14,"51$")+COUNTIF(D14:V14,"52$") -> 3 | AI14: =Predloge!$B$14 -> ☻ | AJ14: =RIGHT(D14,1) -> T | AK14: =RIGHT(E14,1) -> F | AL14: =RIGHT(F14,1) -> T | AM14: =RIGHT(G14,1) -> T | AN14: =RIGHT(H14,1) -> O | AO14: =RIGHT(I14,1) -> 2 | AP14: =RIGHT(J14,1) -> 1 | AQ14: =RIGHT(K14,1) -> X | ... BA14: =RIGHT(U14,1) -> X
B15: 45671 | C15: =TEXT(B15,"Ddd") -> Tue | D15: =Predloge!$B$6 -> KVIT | E15: =Predloge!$B$15 -> SO | F15: =Predloge!$B$6 -> KVIT | G15: =Predloge!$B$6 -> KVIT | H15: KO | I15: =Predloge!$B$32 -> Am | J15: =Predloge!$B$5 -> 52 | K15: =Predloge!$B$6 -> KVIT | L15: =Predloge!$B$26 -> 52¶ | M15: =Predloge!$B$12 -> D | N15: =Predloge!$B$7 -> KVIT☻ | O15: =Predloge!$B$11 -> X | P15: =Predloge!$B$4 -> 51 | Q15: =Predloge!$B$11 -> X | R15: =Predloge!$B$23 -> 51☺ | T15: =Predloge!$B$6 -> KVIT | V15: ŽRJ | W15: ŠTU | X15: =COUNTIF(AJ15:BA15,"☻") -> 1 | Y15: =COUNTIF(AJ15:BA15,"☺") -> 1 | Z15: =COUNTIF(D15:V15,"51")+COUNTIF(D15:V15,"51$")+COUNTIF(D15:V15,"51☻") -> 1 | AA15: =COUNTIF(D15:V15,"52")+COUNTIF(D15:V15,"52$")+COUNTIF(D15:V15,"52☻") -> 1 | AB15: =COUNTIF(D15:V15,"51¶") -> 0 | AC15: =COUNTIF(D15:V15,"52¶") -> 1 | AD15: =COUNTIF(D15:V15,"U")+COUNTIF(D15:V15,"U☻")+COUNTIF(D15:V15,"U☺") -> 0 | AE15: =COUNTIF(D15:V15,"KVIT")+COUNTIF(D15:V15,"KVIT☻")+COUNTIF(D15:V15,"kvit$") -> 6 | AF15: =COUNTBLANK(D15:U15)-3 -> -1 | AG15: =COUNTIF(D15:V15,"x") -> 2 | AH15: =COUNTIF(D15:V15,"51")+COUNTIF(D15:V15,"51☻")+COUNTIF(D15:V15,"2")+COUNTIF(D15:V15,"52")+COUNTIF(D15:V15,"52☻")+COUNTIF(D15:V15,"51$")+COUNTIF(D15:V15,"52$") -> 2 | AI15: =Predloge!$B$15 -> SO | AJ15: =RIGHT(D15,1) -> T | AK15: =RIGHT(E15,1) -> O | AL15: =RIGHT(F15,1) -> T | AM15: =RIGHT(G15,1) -> T | AN15: =RIGHT(H15,1) -> O | AO15: =RIGHT(I15,1) -> m | AP15: =RIGHT(J15,1) -> 2 | AQ15: =RIGHT(K15,1) -> T | ... BA15: =RIGHT(U15,1)
B16: 45672 | C16: =TEXT(B16,"Ddd") -> Wed | D16: =Predloge!$B$5 -> 52 | E16: =Predloge!$B$7 -> KVIT☻ | F16: =Predloge!$B$6 -> KVIT | G16: =Predloge!$B$6 -> KVIT | H16: KO | I16: =Predloge!$B$23 -> 51☺ | J16: =Predloge!$B$12 -> D | K16: =Predloge!$B$35 -> Ta | L16: =Predloge!$B$6 -> KVIT | M16: =Predloge!$B$12 -> D | N16: =Predloge!$B$11 -> X | O16: =Predloge!$B$12 -> D | P16: =Predloge!$B$4 -> 51 | Q16: =Predloge!$B$6 -> KVIT | R16: =Predloge!$B$11 -> X | T16: NPK | U16: =Predloge!$B$26 -> 52¶ | V16: MIO | W16: =Predloge!$E$5 -> KON | X16: =COUNTIF(AJ16:BA16,"☻") -> 1 | Y16: =COUNTIF(AJ16:BA16,"☺") -> 1 | Z16: =COUNTIF(D16:V16,"51")+COUNTIF(D16:V16,"51$")+COUNTIF(D16:V16,"51☻") -> 1 | AA16: =COUNTIF(D16:V16,"52")+COUNTIF(D16:V16,"52$")+COUNTIF(D16:V16,"52☻") -> 1 | AB16: =COUNTIF(D16:V16,"51¶") -> 0 | AC16: =COUNTIF(D16:V16,"52¶") -> 1 | AD16: =COUNTIF(D16:V16,"U")+COUNTIF(D16:V16,"U☻")+COUNTIF(D16:V16,"U☺") -> 0 | AE16: =COUNTIF(D16:V16,"KVIT")+COUNTIF(D16:V16,"KVIT☻")+COUNTIF(D16:V16,"kvit$") -> 5 | AF16: =COUNTBLANK(D16:U16)-3 -> -2 | AG16: =COUNTIF(D16:V16,"x") -> 2 | AH16: =COUNTIF(D16:V16,"51")+COUNTIF(D16:V16,"51☻")+COUNTIF(D16:V16,"2")+COUNTIF(D16:V16,"52")+COUNTIF(D16:V16,"52☻")+COUNTIF(D16:V16,"51$")+COUNTIF(D16:V16,"52$") -> 2 | AI16: =Predloge!$B$16 -> ☻ | AJ16: =RIGHT(D16,1) -> 2 | AK16: =RIGHT(E16,1) -> ☻ | AL16: =RIGHT(F16,1) -> T | AM16: =RIGHT(G16,1) -> T | AN16: =RIGHT(H16,1) -> O | AO16: =RIGHT(I16,1) -> ☺ | AP16: =RIGHT(J16,1) -> D | AQ16: =RIGHT(K16,1) -> a | ... BA16: =RIGHT(U16,1) -> ¶
B17: 45673 | C17: =TEXT(B17,"Ddd") -> Thu | D17: =Predloge!$B$26 -> 52¶ | E17: =Predloge!$B$11 -> X | F17: =Predloge!$B$7 -> KVIT☻ | G17: =Predloge!$B$6 -> KVIT | H17: =Predloge!$B$5 -> 52 | I17: =Predloge!$B$11 -> X | J17: =Predloge!$B$23 -> 51☺ | K17: =Predloge!$B$11 -> X | L17: =Predloge!$B$6 -> KVIT | M17: =Predloge!$B$12 -> D | N17: =Predloge!$B$18 -> 52$ | O17: =Predloge!$B$6 -> KVIT | P17: =Predloge!$B$4 -> 51 | Q17: =Predloge!$B$6 -> KVIT | R17: =Predloge!$B$4 -> 51 | T17: =Predloge!$B$6 -> KVIT | U17: NPK | V17: BOŽ | W17: =Predloge!$E$5 -> KON | X17: =COUNTIF(AJ17:BA17,"☻") -> 1 | Y17: =COUNTIF(AJ17:BA17,"☺") -> 1 | Z17: =COUNTIF(D17:V17,"51")+COUNTIF(D17:V17,"51$")+COUNTIF(D17:V17,"51☻") -> 2 | AA17: =COUNTIF(D17:V17,"52")+COUNTIF(D17:V17,"52$")+COUNTIF(D17:V17,"52☻") -> 2 | AB17: =COUNTIF(D17:V17,"51¶") -> 0 | AC17: =COUNTIF(D17:V17,"52¶") -> 1 | AD17: =COUNTIF(D17:V17,"U")+COUNTIF(D17:V17,"U☻")+COUNTIF(D17:V17,"U☺") -> 0 | AE17: =COUNTIF(D17:V17,"KVIT")+COUNTIF(D17:V17,"KVIT☻")+COUNTIF(D17:V17,"kvit$") -> 6 | AF17: =COUNTBLANK(D17:U17)-3 -> -2 | AG17: =COUNTIF(D17:V17,"x") -> 3 | AH17: =COUNTIF(D17:V17,"51")+COUNTIF(D17:V17,"51☻")+COUNTIF(D17:V17,"2")+COUNTIF(D17:V17,"52")+COUNTIF(D17:V17,"52☻")+COUNTIF(D17:V17,"51$")+COUNTIF(D17:V17,"52$") -> 4 | AI17: =Predloge!$B$17 -> 51$ | AJ17: =RIGHT(D17,1) -> ¶ | AK17: =RIGHT(E17,1) -> X | AL17: =RIGHT(F17,1) -> ☻ | AM17: =RIGHT(G17,1) -> T | AN17: =RIGHT(H17,1) -> 2 | AO17: =RIGHT(I17,1) -> X | AP17: =RIGHT(J17,1) -> ☺ | AQ17: =RIGHT(K17,1) -> X | ... BA17: =RIGHT(U17,1) -> K
B18: 45674 | C18: =TEXT(B18,"Ddd") -> Fri | D18: =Predloge!$B$6 -> KVIT | E18: =Predloge!$B$12 -> D | F18: =Predloge!$B$11 -> X | G18: =Predloge!$B$6 -> KVIT | H18: =Predloge!$B$23 -> 51☺ | I18: =Predloge!$B$11 -> X | J18: =Predloge!$B$11 -> X | K18: =Predloge!$B$12 -> D | L18: =Predloge!$B$6 -> KVIT | M18: =Predloge!$B$12 -> D | N18: MF | O18: =Predloge!$B$5 -> 52 | P18: =Predloge!$B$4 -> 51 | Q18: =Predloge!$B$7 -> KVIT☻ | R18: =Predloge!$B$26 -> 52¶ | T18: =Predloge!$B$6 -> KVIT | V18: ORO | W18: =januar!$R$1 -> ŽRJ | X18: =COUNTIF(AJ18:BA18,"☻") -> 1 | Y18: =COUNTIF(AJ18:BA18,"☺") -> 1 | Z18: =COUNTIF(D18:V18,"51")+COUNTIF(D18:V18,"51$")+COUNTIF(D18:V18,"51☻") -> 1 | AA18: =COUNTIF(D18:V18,"52")+COUNTIF(D18:V18,"52$")+COUNTIF(D18:V18,"52☻") -> 1 | AB18: =COUNTIF(D18:V18,"51¶") -> 0 | AC18: =COUNTIF(D18:V18,"52¶") -> 1 | AD18: =COUNTIF(D18:V18,"U")+COUNTIF(D18:V18,"U☻")+COUNTIF(D18:V18,"U☺") -> 0 | AE18: =COUNTIF(D18:V18,"KVIT")+COUNTIF(D18:V18,"KVIT☻")+COUNTIF(D18:V18,"kvit$") -> 5 | AF18: =COUNTBLANK(D18:U18)-3 -> -1 | AG18: =COUNTIF(D18:V18,"x") -> 3 | AH18: =COUNTIF(D18:V18,"51")+COUNTIF(D18:V18,"51☻")+COUNTIF(D18:V18,"2")+COUNTIF(D18:V18,"52")+COUNTIF(D18:V18,"52☻")+COUNTIF(D18:V18,"51$")+COUNTIF(D18:V18,"52$") -> 2 | AI18: =Predloge!$B$18 -> 52$ | AJ18: =RIGHT(D18,1) -> T | AK18: =RIGHT(E18,1) -> D | AL18: =RIGHT(F18,1) -> X | AM18: =RIGHT(G18,1) -> T | AN18: =RIGHT(H18,1) -> ☺ | AO18: =RIGHT(I18,1) -> X | AP18: =RIGHT(J18,1) -> X | AQ18: =RIGHT(K18,1) -> D | ... BA18: =RIGHT(U18,1)
B19: 45675 | C19: =TEXT(B19,"Ddd") -> Sat | G19: =Predloge!$B$14 -> ☻ | V19: DIV | W19: MIO | X19: =COUNTIF(AJ19:BA19,"☻") -> 1 | Y19: =COUNTIF(AJ19:BA19,"☺") -> 0 | Z19: =COUNTIF(D19:V19,"51")+COUNTIF(D19:V19,"51$")+COUNTIF(D19:V19,"51☻") -> 0 | AA19: =COUNTIF(D19:V19,"52")+COUNTIF(D19:V19,"52$")+COUNTIF(D19:V19,"52☻") -> 0 | AB19: =COUNTIF(D19:V19,"51¶") -> 0 | AC19: =COUNTIF(D19:V19,"52¶") -> 0 | AD19: =COUNTIF(D19:V19,"U")+COUNTIF(D19:V19,"U☻")+COUNTIF(D19:V19,"U☺") -> 0 | AE19: =COUNTIF(D19:V19,"KVIT")+COUNTIF(D19:V19,"KVIT☻")+COUNTIF(D19:V19,"kvit$") -> 0 | AF19: =COUNTBLANK(D19:U19)-3 -> 14 | AG19: =COUNTIF(D19:V19,"x") -> 0 | AH19: =COUNTIF(D19:V19,"51")+COUNTIF(D19:V19,"51☻")+COUNTIF(D19:V19,"2")+COUNTIF(D19:V19,"52")+COUNTIF(D19:V19,"52☻")+COUNTIF(D19:V19,"51$")+COUNTIF(D19:V19,"52$") -> 0 | AI19: =Predloge!$B$19 -> KVIT$ | AJ19: =RIGHT(D19,1) | AK19: =RIGHT(E19,1) | AL19: =RIGHT(F19,1) | AM19: =RIGHT(G19,1) -> ☻ | AN19: =RIGHT(H19,1) | AO19: =RIGHT(I19,1) | AP19: =RIGHT(J19,1) | AQ19: =RIGHT(K19,1) | ... BA19: =RIGHT(U19,1)
B20: 45676 | C20: =TEXT(B20,"Ddd") -> Sun | J20: =Predloge!$B$21 -> ☺ | T20: =Predloge!$B$14 -> ☻ | V20: BOŽ | W20: MIO | X20: =COUNTIF(AJ20:BA20,"☻") -> 1 | Y20: =COUNTIF(AJ20:BA20,"☺") -> 1 | Z20: =COUNTIF(D20:V20,"51")+COUNTIF(D20:V20,"51$")+COUNTIF(D20:V20,"51☻") -> 0 | AA20: =COUNTIF(D20:V20,"52")+COUNTIF(D20:V20,"52$")+COUNTIF(D20:V20,"52☻") -> 0 | AB20: =COUNTIF(D20:V20,"51¶") -> 0 | AC20: =COUNTIF(D20:V20,"52¶") -> 0 | AD20: =COUNTIF(D20:V20,"U")+COUNTIF(D20:V20,"U☻")+COUNTIF(D20:V20,"U☺") -> 0 | AE20: =COUNTIF(D20:V20,"KVIT")+COUNTIF(D20:V20,"KVIT☻")+COUNTIF(D20:V20,"kvit$") -> 0 | AF20: =COUNTBLANK(D20:U20)-3 -> 13 | AG20: =COUNTIF(D20:V20,"x") -> 0 | AH20: =COUNTIF(D20:V20,"51")+COUNTIF(D20:V20,"51☻")+COUNTIF(D20:V20,"2")+COUNTIF(D20:V20,"52")+COUNTIF(D20:V20,"52☻")+COUNTIF(D20:V20,"51$")+COUNTIF(D20:V20,"52$") -> 0 | AI20: =Predloge!$B$20 -> ☺ | AJ20: =RIGHT(D20,1) | AK20: =RIGHT(E20,1) | AL20: =RIGHT(F20,1) | AM20: =RIGHT(G20,1) | AN20: =RIGHT(H20,1) | AO20: =RIGHT(I20,1) | AP20: =RIGHT(J20,1) -> ☺ | AQ20: =RIGHT(K20,1) | ... BA20: =RIGHT(U20,1)
B21: 45677 | C21: =TEXT(B21,"Ddd") -> Mon | D21: =Predloge!$B$6 -> KVIT | E21: =Predloge!$B$6 -> KVIT | F21: =Predloge!$B$26 -> 52¶ | G21: =Predloge!$B$6 -> KVIT | H21: KO | I21: =Predloge!$B$5 -> 52 | J21: =Predloge!$B$11 -> X | K21: =Predloge!$B$6 -> KVIT | L21: =Predloge!$B$6 -> KVIT | M21: =Predloge!$B$4 -> 51 | N21: =Predloge!$B$7 -> KVIT☻ | O21: =Predloge!$B$6 -> KVIT | P21: =Predloge!$B$5 -> 52 | Q21: =[1]Predloge!$B$6 -> KVIT | R21: =Predloge!$B$23 -> 51☺ | T21: =Predloge!$B$11 -> X | V21: ŽRJ | W21: ŠTU | X21: =COUNTIF(AJ21:BA21,"☻") -> 1 | Y21: =COUNTIF(AJ21:BA21,"☺") -> 1 | Z21: =COUNTIF(D21:V21,"51")+COUNTIF(D21:V21,"51$")+COUNTIF(D21:V21,"51☻") -> 1 | AA21: =COUNTIF(D21:V21,"52")+COUNTIF(D21:V21,"52$")+COUNTIF(D21:V21,"52☻") -> 2 | AB21: =COUNTIF(D21:V21,"51¶") -> 0 | AC21: =COUNTIF(D21:V21,"52¶") -> 1 | AD21: =COUNTIF(D21:V21,"U")+COUNTIF(D21:V21,"U☻")+COUNTIF(D21:V21,"U☺") -> 0 | AE21: =COUNTIF(D21:V21,"KVIT")+COUNTIF(D21:V21,"KVIT☻")+COUNTIF(D21:V21,"kvit$") -> 8 | AF21: =COUNTBLANK(D21:U21)-3 -> -1 | AG21: =COUNTIF(D21:V21,"x") -> 2 | AH21: =COUNTIF(D21:V21,"51")+COUNTIF(D21:V21,"51☻")+COUNTIF(D21:V21,"2")+COUNTIF(D21:V21,"52")+COUNTIF(D21:V21,"52☻")+COUNTIF(D21:V21,"51$")+COUNTIF(D21:V21,"52$") -> 3 | AI21: =Predloge!$B$21 -> ☺ | AJ21: =RIGHT(D21,1) -> T | AK21: =RIGHT(E21,1) -> T | AL21: =RIGHT(F21,1) -> ¶ | AM21: =RIGHT(G21,1) -> T | AN21: =RIGHT(H21,1) -> O | AO21: =RIGHT(I21,1) -> 2 | AP21: =RIGHT(J21,1) -> X | AQ21: =RIGHT(K21,1) -> T | ... BA21: =RIGHT(U21,1)
B22: 45678 | C22: =TEXT(B22,"Ddd") -> Tue | D22: =Predloge!$B$6 -> KVIT | E22: =Predloge!$B$6 -> KVIT | F22: =[1]Predloge!$B$6 -> KVIT | G22: =Predloge!$B$26 -> 52¶ | H22: KO | I22: =Predloge!$B$32 -> Am | J22: =Predloge!$B$5 -> 52 | K22: =Predloge!$B$12 -> D | L22: =Predloge!$B$6 -> KVIT | M22: =Predloge!$B$23 -> 51☺ | N22: =Predloge!$B$11 -> X | O22: =Predloge!$B$7 -> KVIT☻ | P22: =Predloge!$B$32 -> Am | Q22: =Predloge!$B$6 -> KVIT | R22: =Predloge!$B$11 -> X | T22: =Predloge!$B$4 -> 51 | U22: NPK | V22: ŽIV | W22: =januar!$J$1 -> BOŽ | X22: =COUNTIF(AJ22:BA22,"☻") -> 1 | Y22: =COUNTIF(AJ22:BA22,"☺") -> 1 | Z22: =COUNTIF(D22:V22,"51")+COUNTIF(D22:V22,"51$")+COUNTIF(D22:V22,"51☻") -> 1 | AA22: =COUNTIF(D22:V22,"52")+COUNTIF(D22:V22,"52$")+COUNTIF(D22:V22,"52☻") -> 1 | AB22: =COUNTIF(D22:V22,"51¶") -> 0 | AC22: =COUNTIF(D22:V22,"52¶") -> 1 | AD22: =COUNTIF(D22:V22,"U")+COUNTIF(D22:V22,"U☻")+COUNTIF(D22:V22,"U☺") -> 0 | AE22: =COUNTIF(D22:V22,"KVIT")+COUNTIF(D22:V22,"KVIT☻")+COUNTIF(D22:V22,"kvit$") -> 6 | AF22: =COUNTBLANK(D22:U22)-3 -> -2 | AG22: =COUNTIF(D22:V22,"x") -> 2 | AH22: =COUNTIF(D22:V22,"51")+COUNTIF(D22:V22,"51☻")+COUNTIF(D22:V22,"2")+COUNTIF(D22:V22,"52")+COUNTIF(D22:V22,"52☻")+COUNTIF(D22:V22,"51$")+COUNTIF(D22:V22,"52$") -> 2 | AI22: =Predloge!$B$22 -> U☺ | AJ22: =RIGHT(D22,1) -> T | AK22: =RIGHT(E22,1) -> T | AL22: =RIGHT(F22,1) -> T | AM22: =RIGHT(G22,1) -> ¶ | AN22: =RIGHT(H22,1) -> O | AO22: =RIGHT(I22,1) -> m | AP22: =RIGHT(J22,1) -> 2 | AQ22: =RIGHT(K22,1) -> D | ... BA22: =RIGHT(U22,1) -> K
B23: 45679 | C23: =TEXT(B23,"Ddd") -> Wed | D23: =Predloge!$B$35 -> Ta | E23: =Predloge!$B$6 -> KVIT | F23: =Predloge!$B$6 -> KVIT | G23: =Predloge!$B$6 -> KVIT | H23: KO | I23: =Predloge!$B$24 -> 52☺ | J23: =Predloge!$B$4 -> 51 | K23: =Predloge!$B$6 -> KVIT | L23: =Predloge!$B$7 -> KVIT☻ | M23: =Predloge!$B$11 -> X | N23: =Predloge!$B$6 -> KVIT | O23: =Predloge!$B$11 -> X | P23: =Predloge!$B$5 -> 52 | Q23: =Predloge!$B$6 -> KVIT | R23: =Predloge!$B$5 -> 52 | T23: =Predloge!$B$4 -> 51 | U23: NPK | V23: MIO | W23: =januar!$J$1 -> BOŽ | X23: =COUNTIF(AJ23:BA23,"☻") -> 1 | Y23: =COUNTIF(AJ23:BA23,"☺") -> 1 | Z23: =COUNTIF(D23:V23,"51")+COUNTIF(D23:V23,"51$")+COUNTIF(D23:V23,"51☻") -> 2 | AA23: =COUNTIF(D23:V23,"52")+COUNTIF(D23:V23,"52$")+COUNTIF(D23:V23,"52☻") -> 2 | AB23: =COUNTIF(D23:V23,"51¶") -> 0 | AC23: =COUNTIF(D23:V23,"52¶") -> 0 | AD23: =COUNTIF(D23:V23,"U")+COUNTIF(D23:V23,"U☻")+COUNTIF(D23:V23,"U☺") -> 0 | AE23: =COUNTIF(D23:V23,"KVIT")+COUNTIF(D23:V23,"KVIT☻")+COUNTIF(D23:V23,"kvit$") -> 7 | AF23: =COUNTBLANK(D23:U23)-3 -> -2 | AG23: =COUNTIF(D23:V23,"x") -> 2 | AH23: =COUNTIF(D23:V23,"51")+COUNTIF(D23:V23,"51☻")+COUNTIF(D23:V23,"2")+COUNTIF(D23:V23,"52")+COUNTIF(D23:V23,"52☻")+COUNTIF(D23:V23,"51$")+COUNTIF(D23:V23,"52$") -> 4 | AI23: =Predloge!$B$23 -> 51☺ | AJ23: =RIGHT(D23,1) -> a | AK23: =RIGHT(E23,1) -> T | AL23: =RIGHT(F23,1) -> T | AM23: =RIGHT(G23,1) -> T | AN23: =RIGHT(H23,1) -> O | AO23: =RIGHT(I23,1) -> ☺ | AP23: =RIGHT(J23,1) -> 1 | AQ23: =RIGHT(K23,1) -> T | ... BA23: =RIGHT(U23,1) -> K
B24: 45680 | C24: =TEXT(B24,"Ddd") -> Thu | D24: =Predloge!$B$12 -> D | E24: =[1]Predloge!$B$6 -> KVIT | F24: =Predloge!$B$6 -> KVIT | G24: =Predloge!$B$7 -> KVIT☻ | H24: =Predloge!$B$4 -> 51 | I24: =Predloge!$B$11 -> X | J24: =Predloge!$B$12 -> D | K24: =Predloge!$B$6 -> KVIT | L24: =Predloge!$B$11 -> X | M24: =Predloge!$B$26 -> 52¶ | N24: =Predloge!$B$6 -> KVIT | O24: =Predloge!$B$12 -> D | P24: =Predloge!$B$11 -> X | Q24: =Predloge!$B$6 -> KVIT | R24: =Predloge!$B$5 -> 52 | T24: =Predloge!$B$23 -> 51☺ | V24: JNK | W24: =januar!$J$1 -> BOŽ | X24: =COUNTIF(AJ24:BA24,"☻") -> 1 | Y24: =COUNTIF(AJ24:BA24,"☺") -> 1 | Z24: =COUNTIF(D24:V24,"51")+COUNTIF(D24:V24,"51$")+COUNTIF(D24:V24,"51☻") -> 1 | AA24: =COUNTIF(D24:V24,"52")+COUNTIF(D24:V24,"52$")+COUNTIF(D24:V24,"52☻") -> 1 | AB24: =COUNTIF(D24:V24,"51¶") -> 0 | AC24: =COUNTIF(D24:V24,"52¶") -> 1 | AD24: =COUNTIF(D24:V24,"U")+COUNTIF(D24:V24,"U☻")+COUNTIF(D24:V24,"U☺") -> 0 | AE24: =COUNTIF(D24:V24,"KVIT")+COUNTIF(D24:V24,"KVIT☻")+COUNTIF(D24:V24,"kvit$") -> 6 | AF24: =COUNTBLANK(D24:U24)-3 -> -1 | AG24: =COUNTIF(D24:V24,"x") -> 3 | AH24: =COUNTIF(D24:V24,"51")+COUNTIF(D24:V24,"51☻")+COUNTIF(D24:V24,"2")+COUNTIF(D24:V24,"52")+COUNTIF(D24:V24,"52☻")+COUNTIF(D24:V24,"51$")+COUNTIF(D24:V24,"52$") -> 2 | AI24: =Predloge!$B$24 -> 52☺ | AJ24: =RIGHT(D30,1) -> T | AK24: =RIGHT(E24,1) -> T | AL24: =RIGHT(F24,1) -> T | AM24: =RIGHT(G24,1) -> ☻ | AN24: =RIGHT(H24,1) -> 1 | AO24: =RIGHT(I24,1) -> X | AP24: =RIGHT(J24,1) -> D | AQ24: =RIGHT(K24,1) -> T | AR24: =RIGHT(L24,1) -> X | ... BA24: =RIGHT(U24,1)
B25: 45681 | C25: =TEXT(B25,"Ddd") -> Fri | D25: =Predloge!$B$6 -> KVIT | E25: =Predloge!$B$11 -> X | F25: =Predloge!$B$6 -> KVIT | G25: =Predloge!$B$11 -> X | H25: =Predloge!$B$23 -> 51☺ | I25: =Predloge!$B$11 -> X | J25: =Predloge!$B$5 -> 52 | K25: =Predloge!$B$7 -> KVIT☻ | L25: =Predloge!$B$6 -> KVIT | M25: =Predloge!$B$4 -> 51 | N25: =Predloge!$B$6 -> KVIT | O25: =Predloge!$B$12 -> D | P25: =Predloge!$B$5 -> 52 | Q25: =Predloge!$B$6 -> KVIT | R25: =Predloge!$B$5 -> 52 | T25: =Predloge!$B$11 -> X | V25: ORO | W25: =januar!$J$1 -> BOŽ | X25: =COUNTIF(AJ25:BA25,"☻") -> 1 | Y25: =COUNTIF(AJ25:BA25,"☺") -> 1 | Z25: =COUNTIF(D25:V25,"51")+COUNTIF(D25:V25,"51$")+COUNTIF(D25:V25,"51☻") -> 1 | AA25: =COUNTIF(D25:V25,"52")+COUNTIF(D25:V25,"52$")+COUNTIF(D25:V25,"52☻") -> 3 | AB25: =COUNTIF(D25:V25,"51¶") -> 0 | AC25: =COUNTIF(D25:V25,"52¶") -> 0 | AD25: =COUNTIF(D25:V25,"U")+COUNTIF(D25:V25,"U☻")+COUNTIF(D25:V25,"U☺") -> 0 | AE25: =COUNTIF(D25:V25,"KVIT")+COUNTIF(D25:V25,"KVIT☻")+COUNTIF(D25:V25,"kvit$") -> 6 | AF25: =COUNTBLANK(D25:U25)-3 -> -1 | AG25: =COUNTIF(D25:V25,"x") -> 4 | AH25: =COUNTIF(D25:V25,"51")+COUNTIF(D25:V25,"51☻")+COUNTIF(D25:V25,"2")+COUNTIF(D25:V25,"52")+COUNTIF(D25:V25,"52☻")+COUNTIF(D25:V25,"51$")+COUNTIF(D25:V25,"52$") -> 4 | AI25: =Predloge!$B$25 -> 51¶ | AJ25: =RIGHT(D25,1) -> T | AK25: =RIGHT(E25,1) -> X | AL25: =RIGHT(F25,1) -> T | AM25: =RIGHT(G25,1) -> X | AN25: =RIGHT(H25,1) -> ☺ | AO25: =RIGHT(I25,1) -> X | AP25: =RIGHT(J25,1) -> 2 | AQ25: =RIGHT(K25,1) -> ☻ | ... BA25: =RIGHT(U25,1)
B26: 45682 | C26: =TEXT(B26,"Ddd") -> Sat | D26: =Predloge!$B$21 -> ☺ | N26: =Predloge!$B$14 -> ☻ | V26: POČ | W26: TOM | X26: =COUNTIF(AJ26:BA26,"☻") -> 1 | Y26: =COUNTIF(AJ26:BA26,"☺") -> 1 | Z26: =COUNTIF(D26:V26,"51")+COUNTIF(D26:V26,"51$")+COUNTIF(D26:V26,"51☻") -> 0 | AA26: =COUNTIF(D26:V26,"52")+COUNTIF(D26:V26,"52$")+COUNTIF(D26:V26,"52☻") -> 0 | AB26: =COUNTIF(D26:V26,"51¶") -> 0 | AC26: =COUNTIF(D26:V26,"52¶") -> 0 | AD26: =COUNTIF(D26:V26,"U")+COUNTIF(D26:V26,"U☻")+COUNTIF(D26:V26,"U☺") -> 0 | AE26: =COUNTIF(D26:V26,"KVIT")+COUNTIF(D26:V26,"KVIT☻")+COUNTIF(D26:V26,"kvit$") -> 0 | AF26: =COUNTBLANK(D26:U26)-3 -> 13 | AG26: =COUNTIF(D26:V26,"x") -> 0 | AH26: =COUNTIF(D26:V26,"51")+COUNTIF(D26:V26,"51☻")+COUNTIF(D26:V26,"2")+COUNTIF(D26:V26,"52")+COUNTIF(D26:V26,"52☻")+COUNTIF(D26:V26,"51$")+COUNTIF(D26:V26,"52$") -> 0 | AI26: =Predloge!$B$26 -> 52¶ | AJ26: =RIGHT(D26,1) -> ☺ | AK26: =RIGHT(E26,1) | AL26: =RIGHT(F26,1) | AM26: =RIGHT(G26,1) | AN26: =RIGHT(H26,1) | AO26: =RIGHT(I26,1) | AP26: =RIGHT(J26,1) | AQ26: =RIGHT(K26,1) | ... BA26: =RIGHT(U26,1)
B27: 45683 | C27: =TEXT(B27,"Ddd") -> Sun | M27: =Predloge!$B$21 -> ☺ | Q27: =Predloge!$B$14 -> ☻ | V27: ŽIV | W27: TOM | X27: =COUNTIF(AJ27:BA27,"☻") -> 1 | Y27: =COUNTIF(AJ27:BA27,"☺") -> 1 | Z27: =COUNTIF(D27:V27,"51")+COUNTIF(D27:V27,"51$")+COUNTIF(D27:V27,"51☻") -> 0 | AA27: =COUNTIF(D27:V27,"52")+COUNTIF(D27:V27,"52$")+COUNTIF(D27:V27,"52☻") -> 0 | AB27: =COUNTIF(D27:V27,"51¶") -> 0 | AC27: =COUNTIF(D27:V27,"52¶") -> 0 | AD27: =COUNTIF(D27:V27,"U")+COUNTIF(D27:V27,"U☻")+COUNTIF(D27:V27,"U☺") -> 0 | AE27: =COUNTIF(D27:V27,"KVIT")+COUNTIF(D27:V27,"KVIT☻")+COUNTIF(D27:V27,"kvit$") -> 0 | AF27: =COUNTBLANK(D27:U27)-3 -> 13 | AG27: =COUNTIF(D27:V27,"x") -> 0 | AH27: =COUNTIF(D27:V27,"51")+COUNTIF(D27:V27,"51☻")+COUNTIF(D27:V27,"2")+COUNTIF(D27:V27,"52")+COUNTIF(D27:V27,"52☻")+COUNTIF(D27:V27,"51$")+COUNTIF(D27:V27,"52$") -> 0 | AI27: =Predloge!$B$27 -> KVIT☺ | AJ27: =RIGHT(D27,1) | AK27: =RIGHT(E27,1) | AL27: =RIGHT(F27,1) | AM27: =RIGHT(G27,1) | AN27: =RIGHT(H27,1) | AO27: =RIGHT(I27,1) | AP27: =RIGHT(J27,1) | AQ27: =RIGHT(K27,1) | ... BA27: =RIGHT(U27,1)
B28: 45684 | C28: =TEXT(B28,"Ddd") -> Mon | D28: =Predloge!$B$6 -> KVIT | E28: =[1]Predloge!$B$6 -> KVIT | F28: =Predloge!$B$26 -> 52¶ | G28: =Predloge!$B$6 -> KVIT | H28: KO | I28: =Predloge!$B$5 -> 52 | J28: =Predloge!$B$5 -> 52 | K28: =Predloge!$B$6 -> KVIT | L28: =Predloge!$B$6 -> KVIT | M28: =Predloge!$B$11 -> X | N28: =Predloge!$B$6 -> KVIT | O28: =Predloge!$B$23 -> 51☺ | P28: =Predloge!$B$4 -> 51 | Q28: =Predloge!$B$11 -> X | R28: =Predloge!$B$5 -> 52 | T28: MF | V28: MIR | W28: KON | X28: =COUNTIF(AJ28:BA28,"☻") -> 0 | Y28: =COUNTIF(AJ28:BA28,"☺") -> 1 | Z28: =COUNTIF(D28:V28,"51")+COUNTIF(D28:V28,"51$")+COUNTIF(D28:V28,"51☻") -> 1 | AA28: =COUNTIF(D28:V28,"52")+COUNTIF(D28:V28,"52$")+COUNTIF(D28:V28,"52☻") -> 3 | AB28: =COUNTIF(D28:V28,"51¶") -> 0 | AC28: =COUNTIF(D28:V28,"52¶") -> 1 | AD28: =COUNTIF(D28:V28,"U")+COUNTIF(D28:V28,"U☻")+COUNTIF(D28:V28,"U☺") -> 0 | AE28: =COUNTIF(D28:V28,"KVIT")+COUNTIF(D28:V28,"KVIT☻")+COUNTIF(D28:V28,"kvit$") -> 6 | AF28: =COUNTBLANK(D28:U28)-3 -> -1 | AG28: =COUNTIF(D28:V28,"x") -> 2 | AH28: =COUNTIF(D28:V28,"51")+COUNTIF(D28:V28,"51☻")+COUNTIF(D28:V28,"2")+COUNTIF(D28:V28,"52")+COUNTIF(D28:V28,"52☻")+COUNTIF(D28:V28,"51$")+COUNTIF(D28:V28,"52$") -> 4 | AI28: =Predloge!$B$28 -> KO | AJ28: =RIGHT(D28,1) -> T | AK28: =RIGHT(E28,1) -> T | AL28: =RIGHT(F28,1) -> ¶ | AM28: =RIGHT(G28,1) -> T | AN28: =RIGHT(H28,1) -> O | AO28: =RIGHT(I28,1) -> 2 | AP28: =RIGHT(J28,1) -> 2 | AQ28: =RIGHT(K28,1) -> T | ... BA28: =RIGHT(U28,1)
B29: 45685 | C29: =TEXT(B29,"Ddd") -> Tue | D29: =Predloge!$B$6 -> KVIT | E29: =Predloge!$B$6 -> KVIT | F29: =Predloge!$B$6 -> KVIT | G29: =Predloge!$B$12 -> D | H29: KO | I29: =Predloge!$B$5 -> 52 | J29: =Predloge!$B$23 -> 51☺ | K29: =Predloge!$B$11 -> X | L29: =Predloge!$B$6 -> KVIT | M29: =Predloge!$B$5 -> 52 | N29: =[1]Predloge!$B$6 -> KVIT | O29: =Predloge!$B$11 -> X | P29: =Predloge!$B$32 -> Am | Q29: =Predloge!$B$6 -> KVIT | R29: =Predloge!$B$26 -> 52¶ | T29: =Predloge!$B$6 -> KVIT | U29: =Predloge!$B$16 -> ☻ | V29: BOŽ | W29: =januar!$Q$1 -> BUT | X29: =COUNTIF(AJ29:BA29,"☻") -> 1 | Y29: =COUNTIF(AJ29:BA29,"☺") -> 1 | Z29: =COUNTIF(D29:V29,"51")+COUNTIF(D29:V29,"51$")+COUNTIF(D29:V29,"51☻") -> 0 | AA29: =COUNTIF(D29:V29,"52")+COUNTIF(D29:V29,"52$")+COUNTIF(D29:V29,"52☻") -> 2 | AB29: =COUNTIF(D29:V29,"51¶") -> 0 | AC29: =COUNTIF(D29:V29,"52¶") -> 1 | AD29: =COUNTIF(D29:V29,"U")+COUNTIF(D29:V29,"U☻")+COUNTIF(D29:V29,"U☺") -> 0 | AE29: =COUNTIF(D29:V29,"KVIT")+COUNTIF(D29:V29,"KVIT☻")+COUNTIF(D29:V29,"kvit$") -> 7 | AF29: =COUNTBLANK(D29:U29)-3 -> -2 | AG29: =COUNTIF(D29:V29,"x") -> 2 | AH29: =COUNTIF(D29:V29,"51")+COUNTIF(D29:V29,"51☻")+COUNTIF(D29:V29,"2")+COUNTIF(D29:V29,"52")+COUNTIF(D29:V29,"52☻")+COUNTIF(D29:V29,"51$")+COUNTIF(D29:V29,"52$") -> 2 | AI29: =Predloge!$B$29 -> Rt | AJ29: =RIGHT(D29,1) -> T | AK29: =RIGHT(E29,1) -> T | AL29: =RIGHT(F29,1) -> T | AM29: =RIGHT(G29,1) -> D | AN29: =RIGHT(H29,1) -> O | AO29: =RIGHT(I29,1) -> 2 | AP29: =RIGHT(J29,1) -> ☺ | AQ29: =RIGHT(K29,1) -> X | ... BA29: =RIGHT(U29,1) -> ☻
B30: 45686 | C30: =TEXT(B30,"Ddd") -> Wed | D30: =Predloge!$B$6 -> KVIT | E30: =Predloge!$B$6 -> KVIT | F30: =Predloge!$B$12 -> D | G30: =Predloge!$B$12 -> D | H30: KO | I30: =Predloge!$B$5 -> 52 | J30: =Predloge!$B$11 -> X | K30: =Predloge!$B$11 -> X | L30: =Predloge!$B$6 -> KVIT | M30: NPK | N30: =Predloge!$B$7 -> KVIT☻ | O30: =Predloge!$B$26 -> 52¶ | P30: =Predloge!$B$4 -> 51 | Q30: =Predloge!$B$6 -> KVIT | R30: =Predloge!$B$23 -> 51☺ | T30: RTG | U30: =Predloge!$B$11 -> X | V30: ŽRJ | W30: =januar!$Q$1 -> BUT | X30: =COUNTIF(AJ30:BA30,"☻") -> 1 | Y30: =COUNTIF(AJ30:BA30,"☺") -> 1 | Z30: =COUNTIF(D30:V30,"51")+COUNTIF(D30:V30,"51$")+COUNTIF(D30:V30,"51☻") -> 1 | AA30: =COUNTIF(D30:V30,"52")+COUNTIF(D30:V30,"52$")+COUNTIF(D30:V30,"52☻") -> 1 | AB30: =COUNTIF(D30:V30,"51¶") -> 0 | AC30: =COUNTIF(D30:V30,"52¶") -> 1 | AD30: =COUNTIF(D30:V30,"U")+COUNTIF(D30:V30,"U☻")+COUNTIF(D30:V30,"U☺") -> 0 | AE30: =COUNTIF(D30:V30,"KVIT")+COUNTIF(D30:V30,"KVIT☻")+COUNTIF(D30:V30,"kvit$") -> 5 | AF30: =COUNTBLANK(D30:U30)-3 -> -2 | AG30: =COUNTIF(D30:V30,"x") -> 3 | AH30: =COUNTIF(D30:V30,"51")+COUNTIF(D30:V30,"51☻")+COUNTIF(D30:V30,"2")+COUNTIF(D30:V30,"52")+COUNTIF(D30:V30,"52☻")+COUNTIF(D30:V30,"51$")+COUNTIF(D30:V30,"52$") -> 2 | AI30: =Predloge!$B$30 -> Rt☻ | AJ30: =RIGHT(D30,1) -> T | AK30: =RIGHT(E30,1) -> T | AL30: =RIGHT(F30,1) -> D | AM30: =RIGHT(G30,1) -> D | AN30: =RIGHT(H30,1) -> O | AO30: =RIGHT(I30,1) -> 2 | AP30: =RIGHT(J30,1) -> X | AQ30: =RIGHT(K30,1) -> X | ... BA30: =RIGHT(U30,1) -> X
B31: 45687 | C31: =TEXT(B31,"Ddd") -> Thu | D31: =Predloge!$B$6 -> KVIT | E31: MF | F31: =Predloge!$B$12 -> D | G31: =Predloge!$B$7 -> KVIT☻ | H31: =Predloge!$B$35 -> Ta | I31: =Predloge!$B$5 -> 52 | J31: =Predloge!$B$18 -> 52$ | K31: =Predloge!$B$15 -> SO | L31: =[1]Predloge!$B$6 -> KVIT | M31: =Predloge!$B$23 -> 51☺ | N31: =Predloge!$B$11 -> X | O31: =Predloge!$B$26 -> 52¶ | P31: =Predloge!$B$4 -> 51 | Q31: =Predloge!$B$6 -> KVIT | R31: =Predloge!$B$11 -> X | T31: NPK | V31: ŽIV | W31: =januar!$Q$1 -> BUT | X31: =COUNTIF(AJ31:BA31,"☻") -> 1 | Y31: =COUNTIF(AJ31:BA31,"☺") -> 1 | Z31: =COUNTIF(D31:V31,"51")+COUNTIF(D31:V31,"51$")+COUNTIF(D31:V31,"51☻") -> 1 | AA31: =COUNTIF(D31:V31,"52")+COUNTIF(D31:V31,"52$")+COUNTIF(D31:V31,"52☻") -> 2 | AB31: =COUNTIF(D31:V31,"51¶") -> 0 | AC31: =COUNTIF(D31:V31,"52¶") -> 1 | AD31: =COUNTIF(D31:V31,"U")+COUNTIF(D31:V31,"U☻")+COUNTIF(D31:V31,"U☺") -> 0 | AE31: =COUNTIF(D31:V31,"KVIT")+COUNTIF(D31:V31,"KVIT☻")+COUNTIF(D31:V31,"kvit$") -> 4 | AF31: =COUNTBLANK(D31:U31)-3 -> -1 | AG31: =COUNTIF(D31:V31,"x") -> 2 | AH31: =COUNTIF(D31:V31,"51")+COUNTIF(D31:V31,"51☻")+COUNTIF(D31:V31,"2")+COUNTIF(D31:V31,"52")+COUNTIF(D31:V31,"52☻")+COUNTIF(D31:V31,"51$")+COUNTIF(D31:V31,"52$") -> 3 | AI31: =Predloge!$B$31 -> Rt☺ | AJ31: =RIGHT(D31,1) -> T | AK31: =RIGHT(E31,1) -> F | AL31: =RIGHT(F31,1) -> D | AM31: =RIGHT(G31,1) -> ☻ | AN31: =RIGHT(H31,1) -> a | AO31: =RIGHT(I31,1) -> 2 | AP31: =RIGHT(J31,1) -> $ | AQ31: =RIGHT(K31,1) -> O | ... BA31: =RIGHT(U31,1)
B32: 45688 | C32: =TEXT(B32,"Ddd") -> Fri | D32: =Predloge!$B$6 -> KVIT | E32: =Predloge!$B$6 -> KVIT | F32: =Predloge!$B$7 -> KVIT☻ | G32: =Predloge!$B$11 -> X | H32: =Predloge!$B$20 -> ☺ | I32: =Predloge!$B$26 -> 52¶ | J32: =Predloge!$B$4 -> 51 | K32: =Predloge!$B$15 -> SO | L32: =Predloge!$B$6 -> KVIT | M32: =Predloge!$B$11 -> X | N32: MF | O32: =Predloge!$B$12 -> D | P32: =Predloge!$B$5 -> 52 | Q32: =Predloge!$B$13 -> BOL | R32: =Predloge!$B$4 -> 51 | T32: =Predloge!$B$6 -> KVIT | V32: ORO | W32: =januar!$Q$1 -> BUT | X32: =COUNTIF(AJ32:BA32,"☻") -> 1 | Y32: =COUNTIF(AJ32:BA32,"☺") -> 1 | Z32: =COUNTIF(D32:V32,"51")+COUNTIF(D32:V32,"51$")+COUNTIF(D32:V32,"51☻") -> 2 | AA32: =COUNTIF(D32:V32,"52")+COUNTIF(D32:V32,"52$")+COUNTIF(D32:V32,"52☻") -> 1 | AB32: =COUNTIF(D32:V32,"51¶") -> 0 | AC32: =COUNTIF(D32:V32,"52¶") -> 1 | AD32: =COUNTIF(D32:V32,"U")+COUNTIF(D32:V32,"U☻")+COUNTIF(D32:V32,"U☺") -> 0 | AE32: =COUNTIF(D32:V32,"KVIT")+COUNTIF(D32:V32,"KVIT☻")+COUNTIF(D32:V32,"kvit$") -> 5 | AF32: =COUNTBLANK(D32:U32)-3 -> -1 | AG32: =COUNTIF(D32:V32,"x") -> 2 | AH32: =COUNTIF(D32:V32,"51")+COUNTIF(D32:V32,"51☻")+COUNTIF(D32:V32,"2")+COUNTIF(D32:V32,"52")+COUNTIF(D32:V32,"52☻")+COUNTIF(D32:V32,"51$")+COUNTIF(D32:V32,"52$") -> 3 | AI32: =Predloge!$B$32 -> Am | AJ32: =RIGHT(D32,1) -> T | AK32: =RIGHT(E32,1) -> T | AL32: =RIGHT(F32,1) -> ☻ | AM32: =RIGHT(G32,1) -> X | AN32: =RIGHT(H32,1) -> ☺ | AO32: =RIGHT(I32,1) -> ¶ | AP32: =RIGHT(J32,1) -> 1 | AQ32: =RIGHT(K32,1) -> O | ... BA32: =RIGHT(U32,1)
AI33: =Predloge!$B$33 -> Am☻
D34: =januar!$D$1 -> POČ | E34: =januar!$E$1 -> ŠOŠ | F34: =januar!$F$1 -> PIN | G34: =januar!$G$1 -> KON | H34: =januar!$H$1 -> ORO | I34: =januar!$I$1 -> MIO | J34: =januar!$J$1 -> BOŽ | K34: =januar!$K$1 -> TOM | L34: =januar!$L$1 -> MŠŠ | M34: =januar!$M$1 -> ŽIV | N34: =januar!$N$1 -> TAL | O34: =januar!$O$1 -> PIR | P34: =januar!$P$1 -> GNE | Q34: =januar!$Q$1 -> BUT | R34: =januar!$R$1 -> ŽRJ | T34: =januar!$T$1 -> JNK | U34: =januar!$U$1 -> ŠTU | AI34: =Predloge!$B$34 -> Am☺
C35: =Predloge!$B$20 -> ☺ | D35: =COUNTIF(AJ2:AJ32,"☺") -> 1 | E35: =COUNTIF(AK2:AK32,"☺") -> 0 | F35: =COUNTIF(AL2:AL32,"☺") -> 0 | G35: =COUNTIF(AM2:AM32,"☺") -> 0 | H35: =COUNTIF(AN2:AN32,"☺") -> 3 | I35: =COUNTIF(AO2:AO32,"☺") -> 2 | J35: =COUNTIF(AP2:AP32,"☺") -> 4 | K35: =COUNTIF(AQ2:AQ32,"☺") -> 0 | ... U35: =COUNTIF(BA2:BA32,"☺") -> 2 | AI35: =Predloge!$B$35 -> Ta
C36: =Predloge!$B$16 -> ☻ | D36: =COUNTIF(AJ3:AJ33,"☻") -> 1 | E36: =COUNTIF(AK3:AK33,"☻") -> 3 | F36: =COUNTIF(AL3:AL33,"☻") -> 2 | G36: =COUNTIF(AM3:AM33,"☻") -> 5 | H36: =COUNTIF(AN3:AN33,"☻") -> 0 | I36: =COUNTIF(AO3:AO33,"☻") -> 0 | J36: =COUNTIF(AP3:AP33,"☻") -> 0 | K36: =COUNTIF(AQ3:AQ33,"☻") -> 2 | ... U36: =COUNTIF(BA3:BA33,"☻") -> 1 | AI36: =Predloge!$B$36 -> Ta☻
C37: =Predloge!$B$42 -> Σ | D37: =SUM(D35:D36) -> 2 | E37: =SUM(E35:E36) -> 3 | F37: =SUM(F35:F36) -> 2 | G37: =SUM(G35:G36) -> 5 | H37: =SUM(H35:H36) -> 3 | I37: =SUM(I35:I36) -> 2 | J37: =SUM(J35:J36) -> 4 | K37: =SUM(K35:K36) -> 2 | ... U37: =SUM(U35:U36) -> 3 | AI37: =Predloge!$B$37 -> Ta☺
C38: =Predloge!$B$6 -> KVIT | D38: =COUNTIF(D2:D32,"KVIT")+COUNTIF(D2:D32,"51KVIT")+COUNTIF(D2:D32,"52KVIT")+COUNTIF(D2:D32,"KVIT$")+COUNTIF(D2:D32,"KVIT☻")+COUNTIF(D2:D32,"KVIT☺") -> 14 | E38: =COUNTIF(E2:E32,"KVIT")+COUNTIF(E2:E32,"51KVIT")+COUNTIF(E2:E32,"52KVIT")+COUNTIF(E2:E32,"KVIT$")+COUNTIF(E2:E32,"KVIT☻")+COUNTIF(E2:E32,"KVIT☺") -> 11 | F38: =COUNTIF(F2:F32,"KVIT")+COUNTIF(F2:F32,"51KVIT")+COUNTIF(F2:F32,"52KVIT")+COUNTIF(F2:F32,"KVIT$")+COUNTIF(F2:F32,"KVIT☻")+COUNTIF(F2:F32,"KVIT☺") -> 14 | G38: =COUNTIF(G2:G32,"KVIT")+COUNTIF(G2:G32,"51KVIT")+COUNTIF(G2:G32,"52KVIT")+COUNTIF(G2:G32,"KVIT$")+COUNTIF(G2:G32,"KVIT☻")+COUNTIF(G2:G32,"KVIT☺") -> 12 | H38: =COUNTIF(H2:H32,"KVIT")+COUNTIF(H2:H32,"51KVIT")+COUNTIF(H2:H32,"52KVIT")+COUNTIF(H2:H32,"KVIT$")+COUNTIF(H2:H32,"KVIT☻")+COUNTIF(H2:H32,"KVIT☺") -> 0 | I38: =COUNTIF(I2:I32,"KVIT")+COUNTIF(I2:I32,"51KVIT")+COUNTIF(I2:I32,"52KVIT")+COUNTIF(I2:I32,"KVIT$")+COUNTIF(I2:I32,"KVIT☻")+COUNTIF(I2:I32,"KVIT☺") -> 0 | J38: =COUNTIF(J2:J32,"KVIT")+COUNTIF(J2:J32,"51KVIT")+COUNTIF(J2:J32,"52KVIT")+COUNTIF(J2:J32,"KVIT$")+COUNTIF(J2:J32,"KVIT☻")+COUNTIF(J2:J32,"KVIT☺") -> 0 | K38: =COUNTIF(K2:K32,"KVIT")+COUNTIF(K2:K32,"51KVIT")+COUNTIF(K2:K32,"52KVIT")+COUNTIF(K2:K32,"KVIT$")+COUNTIF(K2:K32,"KVIT☻")+COUNTIF(K2:K32,"KVIT☺") -> 10 | ... U38: =COUNTIF(U2:U32,"KVIT")+COUNTIF(U2:U32,"51KVIT")+COUNTIF(U2:U32,"52KVIT")+COUNTIF(U2:U32,"KVIT$")+COUNTIF(U2:U32,"KVIT☻")+COUNTIF(U2:U32,"KVIT☺") -> 0 | AI38: =Predloge!$B$38 -> Rf
C39: =Predloge!$B$43 -> $ | D39: =COUNTIF(D2:D32,"51$")+COUNTIF(D2:D32,"52$")+COUNTIF(D2:D32,"kvit$") -> 0 | E39: =COUNTIF(E2:E32,"51$")+COUNTIF(E2:E32,"52$")+COUNTIF(E2:E32,"kvit$") -> 0 | F39: =COUNTIF(F2:F32,"51$")+COUNTIF(F2:F32,"52$")+COUNTIF(F2:F32,"kvit$") -> 0 | G39: =COUNTIF(G2:G32,"51$")+COUNTIF(G2:G32,"52$")+COUNTIF(G2:G32,"kvit$") -> 0 | H39: =COUNTIF(H2:H32,"51$")+COUNTIF(H2:H32,"52$")+COUNTIF(H2:H32,"kvit$") -> 0 | I39: =COUNTIF(I2:I32,"51$")+COUNTIF(I2:I32,"52$")+COUNTIF(I2:I32,"kvit$") -> 0 | J39: =COUNTIF(J2:J32,"51$")+COUNTIF(J2:J32,"52$")+COUNTIF(J2:J32,"kvit$") -> 1 | K39: =COUNTIF(K2:K32,"51$")+COUNTIF(K2:K32,"52$")+COUNTIF(K2:K32,"kvit$") -> 0 | ... U39: =COUNTIF(U2:U32,"51$")+COUNTIF(U2:U32,"52$")+COUNTIF(U2:U32,"kvit$") -> 0 | AI39: =Predloge!$B$39 -> Rf☻
C40: =Predloge!$B$12 -> D | D40: =COUNTIF(D2:D32,"D") -> 1 | E40: =COUNTIF(E2:E32,"D") -> 3 | F40: =COUNTIF(F2:F32,"D") -> 3 | G40: =COUNTIF(G2:G32,"D") -> 2 | H40: =COUNTIF(H2:H32,"D") -> 6 | I40: =COUNTIF(I2:I32,"D") -> 2 | J40: =COUNTIF(J2:J32,"D") -> 3 | K40: =COUNTIF(K2:K32,"D") -> 3 | ... U40: =COUNTIF(U2:U32,"D") -> 1 | AI40: =Predloge!$B$40 -> Rf☺
...

Sheet februar
A1: praznik | B1: =Predloge!$A$1 -> 2025 | D1: =Predloge!$E$2 -> POČ | E1: =Predloge!$E$3 -> ŠOŠ | F1: =Predloge!$E$4 -> PIN | G1: =Predloge!$E$5 -> KON | H1: =Predloge!$E$6 -> ORO | I1: =Predloge!$E$7 -> MIO | J1: =Predloge!$E$8 -> BOŽ | K1: =Predloge!$E$9 -> TOM | L1: =Predloge!$E$10 -> MŠŠ | M1: =Predloge!$E$11 -> ŽIV | N1: =Predloge!$E$12 -> TAL | O1: =Predloge!$E$13 -> PIR | P1: =Predloge!$E$14 -> GNE | Q1: =Predloge!$E$15 -> BUT | R1: =Predloge!$E$16 -> ŽRJ | S1: =Predloge!$E$17 -> NOV3 | T1: =Predloge!$E$18 -> JNK | U1: =Predloge!$E$19 -> ŠTU | V1: ZUN | W1: TX | X1: ☻ | Y1: ☺ | Z1: =Predloge!$B$4 -> 51 | AA1: =Predloge!$B$5 -> 52 | AB1: =Predloge!$B$25 -> 51¶ | AC1: =Predloge!$B$26 -> 52¶ | AD1: =Predloge!$B$8 -> U | AE1: =Predloge!$B$6 -> KVIT | AF1: Brez | AG1: X | AH1: Op | AJ1: =Predloge!$E$2 -> POČ | AK1: =Predloge!$E$3 -> ŠOŠ | AL1: =Predloge!$E$4 -> PIN | AM1: =Predloge!$E$5 -> KON | AN1: =Predloge!$E$6 -> ORO | AO1: =Predloge!$E$7 -> MIO | AP1: =Predloge!$E$8 -> BOŽ | AQ1: =Predloge!$E$9 -> TOM | AR1: =Predloge!$E$10 -> MŠŠ | AS1: =Predloge!$E$11 -> ŽIV | AT1: =Predloge!$E$12 -> TAL | AU1: =Predloge!$E$13 -> PIR | AV1: =Predloge!$E$14 -> GNE | AW1: =Predloge!$E$15 -> BUT | AX1: =Predloge!$E$16 -> ŽRJ | AY1: =Predloge!$E$17 -> NOV3 | AZ1: =Predloge!$E$18 -> JNK | BA1: =Predloge!$E$19 -> ŠTU
B2: 45689 | C2: =TEXT(B2,"Ddd") -> Sat | J2: =Predloge!$B$21 -> ☺ | T2: =Predloge!$B$14 -> ☻ | V2: BOŽ | W2: MIO | X2: =COUNTIF(AJ2:BA2,"☻") -> 1 | Y2: =COUNTIF(AJ2:BA2,"☺") -> 1 | Z2: =COUNTIF(D2:V2,"51")+COUNTIF(D2:V2,"51$")+COUNTIF(D2:V2,"51☻") -> 0 | AA2: =COUNTIF(D2:V2,"52")+COUNTIF(D2:V2,"52$")+COUNTIF(D2:V2,"52☻") -> 0 | AB2: =COUNTIF(D2:V2,"51¶") -> 0 | AC2: =COUNTIF(D2:V2,"52¶") -> 0 | AD2: =COUNTIF(D2:V2,"U")+COUNTIF(D2:V2,"U☻")+COUNTIF(D2:V2,"U☺") -> 0 | AE2: =COUNTIF(D2:V2,"KVIT")+COUNTIF(D2:V2,"KVIT☻")+COUNTIF(D2:V2,"kvit$") -> 0 | AF2: =COUNTBLANK(D2:U2)-3 -> 13 | AG2: =COUNTIF(D2:V2,"x") -> 0 | AH2: =COUNTIF(D2:V2,"51")+COUNTIF(D2:V2,"51☻")+COUNTIF(D2:V2,"2")+COUNTIF(D2:V2,"52")+COUNTIF(D2:V2,"52☻")+COUNTIF(D2:V2,"51$")+COUNTIF(D2:V2,"52$") -> 0 | AI2: =Predloge!$B$2 -> 51☻ | AJ2: =RIGHT(D2,1) | AK2: =RIGHT(E2,1) | AL2: =RIGHT(F2,1) | AM2: =RIGHT(G2,1) | AN2: =RIGHT(H2,1) | AO2: =RIGHT(I2,1) | AP2: =RIGHT(J2,1) -> ☺ | AQ2: =RIGHT(K2,1) | ... BA2: =RIGHT(U2,1)
B3: 45690 | C3: =TEXT(B3,"Ddd") -> Sun | L3: =Predloge!$B$14 -> ☻ | R3: =Predloge!$B$21 -> ☺ | V3: ŽRJ | W3: JNK | X3: =COUNTIF(AJ3:BA3,"☻") -> 1 | Y3: =COUNTIF(AJ3:BA3,"☺") -> 1 | Z3: =COUNTIF(D3:V3,"51")+COUNTIF(D3:V3,"51$")+COUNTIF(D3:V3,"51☻") -> 0 | AA3: =COUNTIF(D3:V3,"52")+COUNTIF(D3:V3,"52$")+COUNTIF(D3:V3,"52☻") -> 0 | AB3: =COUNTIF(D3:V3,"51¶") -> 0 | AC3: =COUNTIF(D3:V3,"52¶") -> 0 | AD3: =COUNTIF(D3:V3,"U")+COUNTIF(D3:V3,"U☻")+COUNTIF(D3:V3,"U☺") -> 0 | AE3: =COUNTIF(D3:V3,"KVIT")+COUNTIF(D3:V3,"KVIT☻")+COUNTIF(D3:V3,"kvit$") -> 0 | AF3: =COUNTBLANK(D3:U3)-3 -> 13 | AG3: =COUNTIF(D3:V3,"x") -> 0 | AH3: =COUNTIF(D3:V3,"51")+COUNTIF(D3:V3,"51☻")+COUNTIF(D3:V3,"2")+COUNTIF(D3:V3,"52")+COUNTIF(D3:V3,"52☻")+COUNTIF(D3:V3,"51$")+COUNTIF(D3:V3,"52$") -> 0 | AI3: =Predloge!$B$3 -> 52☻ | AJ3: =RIGHT(D3,1) | AK3: =RIGHT(E3,1) | AL3: =RIGHT(F3,1) | AM3: =RIGHT(G3,1) | AN3: =RIGHT(H3,1) | AO3: =RIGHT(I3,1) | AP3: =RIGHT(J3,1) | AQ3: =RIGHT(K3,1) | ... BA3: =RIGHT(U3,1)
B4: 45691 | C4: =TEXT(B4,"Ddd") -> Mon | D4: =Predloge!$B$6 -> KVIT | E4: =Predloge!$B$6 -> KVIT | F4: =[1]Predloge!$B$6 -> KVIT | G4: =Predloge!$B$23 -> 51☺ | H4: KO | I4: =Predloge!$B$26 -> 52¶ | J4: =Predloge!$B$4 -> 51 | K4: =Predloge!$B$6 -> KVIT | L4: =Predloge!$B$11 -> X | M4: =Predloge!$B$5 -> 52 | N4: =Predloge!$B$7 -> KVIT☻ | O4: =Predloge!$B$6 -> KVIT | P4: =Predloge!$B$4 -> 51 | Q4: =Predloge!$B$6 -> KVIT | R4: =Predloge!$B$11 -> X | T4: MF | U4: =Predloge!$B$6 -> KVIT | V4: KON | W4: =Predloge!$E$8 -> BOŽ | X4: =COUNTIF(AJ4:BA4,"☻") -> 1 | Y4: =COUNTIF(AJ4:BA4,"☺") -> 1 | Z4: =COUNTIF(D4:V4,"51")+COUNTIF(D4:V4,"51$")+COUNTIF(D4:V4,"51☻") -> 2 | AA4: =COUNTIF(D4:V4,"52")+COUNTIF(D4:V4,"52$")+COUNTIF(D4:V4,"52☻") -> 1 | AB4: =COUNTIF(D4:V4,"51¶") -> 0 | AC4: =COUNTIF(D4:V4,"52¶") -> 1 | AD4: =COUNTIF(D4:V4,"U")+COUNTIF(D4:V4,"U☻")+COUNTIF(D4:V4,"U☺") -> 0 | AE4: =COUNTIF(D4:V4,"KVIT")+COUNTIF(D4:V4,"KVIT☻")+COUNTIF(D4:V4,"kvit$") -> 8 | AF4: =COUNTBLANK(D4:U4)-3 -> -2 | AG4: =COUNTIF(D4:V4,"x") -> 2 | AH4: =COUNTIF(D4:V4,"51")+COUNTIF(D4:V4,"51☻")+COUNTIF(D4:V4,"2")+COUNTIF(D4:V4,"52")+COUNTIF(D4:V4,"52☻")+COUNTIF(D4:V4,"51$")+COUNTIF(D4:V4,"52$") -> 3 | AI4: =Predloge!$B$4 -> 51 | AJ4: =RIGHT(D4,1) -> T | AK4: =RIGHT(E4,1) -> T | AL4: =RIGHT(F4,1) -> T | AM4: =RIGHT(G4,1) -> ☺ | AN4: =RIGHT(H4,1) -> O | AO4: =RIGHT(I4,1) -> ¶ | AP4: =RIGHT(J4,1) -> 1 | AQ4: =RIGHT(K4,1) -> T | ... BA4: =RIGHT(U4,1) -> T
B5: 45692 | C5: =TEXT(B5,"Ddd") -> Tue | D5: =Predloge!$B$6 -> KVIT | E5: =Predloge!$B$26 -> 52¶ | F5: =[1]Predloge!$B$6 -> KVIT | G5: =Predloge!$B$11 -> X | H5: KO | I5: =Predloge!$B$5 -> 52 | J5: =Predloge!$B$4 -> 51 | K5: =Predloge!$B$11 -> X | L5: =Predloge!$B$6 -> KVIT | M5: NPK | N5: =Predloge!$B$11 -> X | O5: =Predloge!$B$32 -> Am | P5: =Predloge!$B$4 -> 51 | Q5: =Predloge!$B$7 -> KVIT☻ | R5: =Predloge!$B$23 -> 51☺ | T5: NPK | U5: =Predloge!$B$6 -> KVIT | V5: ŽRJ | W5: =Predloge!$E$8 -> BOŽ | X5: =COUNTIF(AJ5:BA5,"☻") -> 1 | Y5: =COUNTIF(AJ5:BA5,"☺") -> 1 | Z5: =COUNTIF(D5:V5,"51")+COUNTIF(D5:V5,"51$")+COUNTIF(D5:V5,"51☻") -> 2 | AA5: =COUNTIF(D5:V5,"52")+COUNTIF(D5:V5,"52$")+COUNTIF(D5:V5,"52☻") -> 1 | AB5: =COUNTIF(D5:V5,"51¶") -> 0 | AC5: =COUNTIF(D5:V5,"52¶") -> 1 | AD5: =COUNTIF(D5:V5,"U")+COUNTIF(D5:V5,"U☻")+COUNTIF(D5:V5,"U☺") -> 0 | AE5: =COUNTIF(D5:V5,"KVIT")+COUNTIF(D5:V5,"KVIT☻")+COUNTIF(D5:V5,"kvit$") -> 5 | AF5: =COUNTBLANK(D5:U5)-3 -> -2 | AG5: =COUNTIF(D5:V5,"x") -> 3 | AH5: =COUNTIF(D5:V5,"51")+COUNTIF(D5:V5,"51☻")+COUNTIF(D5:V5,"2")+COUNTIF(D5:V5,"52")+COUNTIF(D5:V5,"52☻")+COUNTIF(D5:V5,"51$")+COUNTIF(D5:V5,"52$") -> 3 | AI5: =Predloge!$B$5 -> 52 | AJ5: =RIGHT(D5,1) -> T | AK5: =RIGHT(E5,1) -> ¶ | AL5: =RIGHT(F5,1) -> T | AM5: =RIGHT(G5,1) -> X | AN5: =RIGHT(H5,1) -> O | AO5: =RIGHT(I5,1) -> 2 | AP5: =RIGHT(J5,1) -> 1 | AQ5: =RIGHT(K5,1) -> X | ... BA5: =RIGHT(U5,1) -> T
B6: 45693 | C6: =TEXT(B6,"Ddd") -> Wed | D6: =Predloge!$B$6 -> KVIT | E6: MF | F6: =Predloge!$B$6 -> KVIT | G6: =Predloge!$B$35 -> Ta | H6: =Predloge!$B$20 -> ☺ | I6: =Predloge!$B$5 -> 52 | J6: =Predloge!$B$4 -> 51 | K6: =Predloge!$B$6 -> KVIT | L6: =Predloge!$B$26 -> 52¶ | M6: NPK | N6: =Predloge!$B$6 -> KVIT | O6: =Predloge!$B$4 -> 51 | P6: =Predloge!$B$4 -> 51 | Q6: =Predloge!$B$11 -> X | R6: =Predloge!$B$11 -> X | T6: =Predloge!$B$6 -> KVIT | U6: =Predloge!$B$6 -> KVIT | V6: MIR | W6: =Predloge!$E$8 -> BOŽ | X6: =COUNTIF(AJ6:BA6,"☻") -> 0 | Y6: =COUNTIF(AJ6:BA6,"☺") -> 1 | Z6: =COUNTIF(D6:V6,"51")+COUNTIF(D6:V6,"51$")+COUNTIF(D6:V6,"51☻") -> 3 | AA6: =COUNTIF(D6:V6,"52")+COUNTIF(D6:V6,"52$")+COUNTIF(D6:V6,"52☻") -> 1 | AB6: =COUNTIF(D6:V6,"51¶") -> 0 | AC6: =COUNTIF(D6:V6,"52¶") -> 1 | AD6: =COUNTIF(D6:V6,"U")+COUNTIF(D6:V6,"U☻")+COUNTIF(D6:V6,"U☺") -> 0 | AE6: =COUNTIF(D6:V6,"KVIT")+COUNTIF(D6:V6,"KVIT☻")+COUNTIF(D6:V6,"kvit$") -> 6 | AF6: =COUNTBLANK(D6:U6)-3 -> -2 | AG6: =COUNTIF(D6:V6,"x") -> 2 | AH6: =COUNTIF(D6:V6,"51")+COUNTIF(D6:V6,"51☻")+COUNTIF(D6:V6,"2")+COUNTIF(D6:V6,"52")+COUNTIF(D6:V6,"52☻")+COUNTIF(D6:V6,"51$")+COUNTIF(D6:V6,"52$") -> 4 | AI6: =Predloge!$B$6 -> KVIT | AJ6: =RIGHT(D6,1) -> T | AK6: =RIGHT(E6,1) -> F | AL6: =RIGHT(F6,1) -> T | AM6: =RIGHT(G6,1) -> a | AN6: =RIGHT(H6,1) -> ☺ | AO6: =RIGHT(I6,1) -> 2 | AP6: =RIGHT(J6,1) -> 1 | AQ6: =RIGHT(K6,1) -> T | ... BA6: =RIGHT(U6,1) -> T
B7: 45694 | C7: =TEXT(B7,"Ddd") -> Thu | D7: =Predloge!$B$6 -> KVIT | E7: =Predloge!$B$12 -> D | F7: =Predloge!$B$12 -> D | G7: =Predloge!$B$26 -> 52¶ | H7: =Predloge!$B$11 -> X | I7: =Predloge!$B$5 -> 52 | J7: =Predloge!$B$4 -> 51 | K7: =Predloge!$B$7 -> KVIT☻ | L7: =[1]Predloge!$B$6 -> KVIT | M7: =Predloge!$B$5 -> 52 | N7: NPK | O7: =Predloge!$B$23 -> 51☺ | P7: =Predloge!$B$12 -> D | Q7: =Predloge!$B$15 -> SO | R7: NPK | T7: =Predloge!$B$13 -> BOL | U7: =Predloge!$B$6 -> KVIT | V7: PIR | W7: =Predloge!$E$8 -> BOŽ | X7: =COUNTIF(AJ7:BA7,"☻") -> 1 | Y7: =COUNTIF(AJ7:BA7,"☺") -> 1 | Z7: =COUNTIF(D7:V7,"51")+COUNTIF(D7:V7,"51$")+COUNTIF(D7:V7,"51☻") -> 1 | AA7: =COUNTIF(D7:V7,"52")+COUNTIF(D7:V7,"52$")+COUNTIF(D7:V7,"52☻") -> 2 | AB7: =COUNTIF(D7:V7,"51¶") -> 0 | AC7: =COUNTIF(D7:V7,"52¶") -> 1 | AD7: =COUNTIF(D7:V7,"U")+COUNTIF(D7:V7,"U☻")+COUNTIF(D7:V7,"U☺") -> 0 | AE7: =COUNTIF(D7:V7,"KVIT")+COUNTIF(D7:V7,"KVIT☻")+COUNTIF(D7:V7,"kvit$") -> 4 | AF7: =COUNTBLANK(D7:U7)-3 -> -2 | AG7: =COUNTIF(D7:V7,"x") -> 1 | AH7: =COUNTIF(D7:V7,"51")+COUNTIF(D7:V7,"51☻")+COUNTIF(D7:V7,"2")+COUNTIF(D7:V7,"52")+COUNTIF(D7:V7,"52☻")+COUNTIF(D7:V7,"51$")+COUNTIF(D7:V7,"52$") -> 3 | AI7: =Predloge!$B$7 -> KVIT☻ | AJ7: =RIGHT(D7,1) -> T | AK7: =RIGHT(E7,1) -> D | AL7: =RIGHT(F7,1) -> D | AM7: =RIGHT(G7,1) -> ¶ | AN7: =RIGHT(H7,1) -> X | AO7: =RIGHT(I7,1) -> 2 | AP7: =RIGHT(J7,1) -> 1 | AQ7: =RIGHT(K7,1) -> ☻ | ... BA7: =RIGHT(U7,1) -> T
B8: 45695 | C8: =TEXT(B8,"Ddd") -> Fri | D8: =Predloge!$B$23 -> 51☺ | E8: =Predloge!$B$6 -> KVIT | F8: =Predloge!$B$12 -> D | G8: =Predloge!$B$6 -> KVIT | H8: =Predloge!$B$11 -> X | I8: =Predloge!$B$5 -> 52 | J8: =Predloge!$B$4 -> 51 | K8: =Predloge!$B$11 -> X | L8: =Predloge!$B$6 -> KVIT | M8: =Predloge!$B$5 -> 52 | N8: MF | O8: =Predloge!$B$11 -> X | P8: =Predloge!$B$4 -> 51 | Q8: =Predloge!$B$7 -> KVIT☻ | R8: NPK | T8: =Predloge!$B$13 -> BOL | U8: =Predloge!$B$6 -> KVIT | V8: POČ | W8: MIO | X8: =COUNTIF(AJ8:BA8,"☻") -> 1 | Y8: =COUNTIF(AJ8:BA8,"☺") -> 1 | Z8: =COUNTIF(D8:V8,"51")+COUNTIF(D8:V8,"51$")+COUNTIF(D8:V8,"51☻") -> 2 | AA8: =COUNTIF(D8:V8,"52")+COUNTIF(D8:V8,"52$")+COUNTIF(D8:V8,"52☻") -> 2 | AB8: =COUNTIF(D8:V8,"51¶") -> 0 | AC8: =COUNTIF(D8:V8,"52¶") -> 0 | AD8: =COUNTIF(D8:V8,"U")+COUNTIF(D8:V8,"U☻")+COUNTIF(D8:V8,"U☺") -> 0 | AE8: =COUNTIF(D8:V8,"KVIT")+COUNTIF(D8:V8,"KVIT☻")+COUNTIF(D8:V8,"kvit$") -> 5 | AF8: =COUNTBLANK(D8:U8)-3 -> -2 | AG8: =COUNTIF(D8:V8,"x") -> 3 | AH8: =COUNTIF(D8:V8,"51")+COUNTIF(D8:V8,"51☻")+COUNTIF(D8:V8,"2")+COUNTIF(D8:V8,"52")+COUNTIF(D8:V8,"52☻")+COUNTIF(D8:V8,"51$")+COUNTIF(D8:V8,"52$") -> 4 | AI8: =Predloge!$B$8 -> U | AJ8: =RIGHT(D8,1) -> ☺ | AK8: =RIGHT(E8,1) -> T | AL8: =RIGHT(F8,1) -> D | AM8: =RIGHT(G8,1) -> T | AN8: =RIGHT(H8,1) -> X | AO8: =RIGHT(I8,1) -> 2 | AP8: =RIGHT(J8,1) -> 1 | AQ8: =RIGHT(K8,1) -> X | ... BA8: =RIGHT(U8,1) -> T
A9: 1 | B9: 45696 | C9: =TEXT(B9,"Ddd") -> Sat | E9: =Predloge!$B$14 -> ☻ | R9: =Predloge!$B$21 -> ☺ | V9: ŽRJ | W9: MIO | X9: =COUNTIF(AJ9:BA9,"☻") -> 1 | Y9: =COUNTIF(AJ9:BA9,"☺") -> 1 | Z9: =COUNTIF(D9:V9,"51")+COUNTIF(D9:V9,"51$")+COUNTIF(D9:V9,"51☻") -> 0 | AA9: =COUNTIF(D9:V9,"52")+COUNTIF(D9:V9,"52$")+COUNTIF(D9:V9,"52☻") -> 0 | AB9: =COUNTIF(D9:V9,"51¶") -> 0 | AC9: =COUNTIF(D9:V9,"52¶") -> 0 | AD9: =COUNTIF(D9:V9,"U")+COUNTIF(D9:V9,"U☻")+COUNTIF(D9:V9,"U☺") -> 0 | AE9: =COUNTIF(D9:V9,"KVIT")+COUNTIF(D9:V9,"KVIT☻")+COUNTIF(D9:V9,"kvit$") -> 0 | AF9: =COUNTBLANK(D9:U9)-3 -> 13 | AG9: =COUNTIF(D9:V9,"x") -> 0 | AH9: =COUNTIF(D9:V9,"51")+COUNTIF(D9:V9,"51☻")+COUNTIF(D9:V9,"2")+COUNTIF(D9:V9,"52")+COUNTIF(D9:V9,"52☻")+COUNTIF(D9:V9,"51$")+COUNTIF(D9:V9,"52$") -> 0 | AI9: =Predloge!$B$9 -> U☻ | AJ9: =RIGHT(D9,1) | AK9: =RIGHT(E9,1) -> ☻ | AL9: =RIGHT(F9,1) | AM9: =RIGHT(G9,1) | AN9: =RIGHT(H9,1) | AO9: =RIGHT(I9,1) | AP9: =RIGHT(J9,1) | AQ9: =RIGHT(K9,1) | ... BA9: =RIGHT(U9,1)
